<?xml version="1.0"?>
<sdf version="1.9">
  <model name="mecanum_wheel_left">
    <link name="wheel_link">
      <pose>0 0 0 0 0 0</pose>
      <inertial>
        <pose>0 0 0 0 0 0</pose>
        <mass>0.045</mass>
        <inertia>
          <ixx>3.44913E-05</ixx>
          <ixy>0</ixy>
          <ixz>0</ixz>
          <iyy>3.44913E-05</iyy>
          <iyz>0</iyz>
          <izz>5.02327E-05</izz>
        </inertia>
      </inertial>
      <collision name="wheel1_collision">
        <pose>0 0 0.0225 0 0 0</pose>
        <geometry>
          <cylinder>
            <radius>0.04725</radius>
            <length>0.005</length>
          </cylinder>
        </geometry>
      </collision>
      <collision name="wheel2_collision">
        <pose>0 0 -0.0225 0 0 0</pose>
        <geometry>
          <cylinder>
            <radius>0.04725</radius>
            <length>0.005</length>
          </cylinder>
        </geometry>
      </collision>
      <visual name="wheel_visual">
        <geometry>
          <mesh>
            <uri>models://mecanum_wheel_left/meshes/mecanum_wheel_frame_left.stl</uri>
          </mesh>
        </geometry>
        <material>
          <ambient>0.5 0.5 0.5</ambient>
          <diffuse>0.5 0.5 0.5</diffuse>
          <specular>0.1 0.1 0.1</specular>
        </material>
      </visual>

      <!-- <visual name="roller_1_visual">
        <geometry>
          <mesh>
            <uri>models://mecanum_wheel_left/meshes/mecanum_wheel_roller.stl</uri>
          </mesh>
        </geometry>
        <material>
          <ambient>0.1 0.1 0.1</ambient>
          <diffuse>0.1 0.1 0.1</diffuse>
          <specular>0.1 0.1 0.1</specular>
        </material>
      </visual>

      <visual name="roller_2_visual">
        <pose degrees="true">0.030862619 0.025896812 0 -45 2 40</pose>
        <geometry>
          <mesh>
            <uri>models://mecanum_wheel_left/meshes/mecanum_wheel_roller.stl</uri>
          </mesh>
        </geometry>
        <material>
          <ambient>0.5 0.5 0.5</ambient>
          <diffuse>0.5 0.5 0.5</diffuse>
          <specular>0.1 0.1 0.1</specular>
        </material>
      </visual>

      <visual name="roller_3_visual">
        <pose degrees="true">0.006995988 0.039676218 0 -45 2 80</pose>
        <geometry>
          <mesh>
            <uri>models://mecanum_wheel_left/meshes/mecanum_wheel_roller.stl</uri>
          </mesh>
        </geometry>
        <material>
          <ambient>0.5 0.5 0.5</ambient>
          <diffuse>0.5 0.5 0.5</diffuse>
          <specular>0.1 0.1 0.1</specular>
        </material>
      </visual>

      <visual name="roller_4_visual">
        <pose degrees="true">-0.020144144 0.034890681 0 -45 2 120</pose>
        <geometry>
          <mesh>
            <uri>models://mecanum_wheel_left/meshes/mecanum_wheel_roller.stl</uri>
          </mesh>
        </geometry>
        <material>
          <ambient>0.5 0.5 0.5</ambient>
          <diffuse>0.5 0.5 0.5</diffuse>
          <specular>0.1 0.1 0.1</specular>
        </material>
      </visual>

      <visual name="roller_5_visual">
        <pose degrees="true">-0.037858607 0.013779406 0 -45 2 160</pose>
        <geometry>
          <mesh>
            <uri>models://mecanum_wheel_left/meshes/mecanum_wheel_roller.stl</uri>
          </mesh>
        </geometry>
        <material>
          <ambient>0.5 0.5 0.5</ambient>
          <diffuse>0.5 0.5 0.5</diffuse>
          <specular>0.1 0.1 0.1</specular>
        </material>
      </visual>

      <visual name="roller_6_visual">
        <pose degrees="true">-0.037858607 -0.013779406 0 -45 2 200</pose>
        <geometry>
          <mesh>
            <uri>models://mecanum_wheel_left/meshes/mecanum_wheel_roller.stl</uri>
          </mesh>
        </geometry>
        <material>
          <ambient>0.5 0.5 0.5</ambient>
          <diffuse>0.5 0.5 0.5</diffuse>
          <specular>0.1 0.1 0.1</specular>
        </material>
      </visual>

      <visual name="roller_7_visual">
        <pose degrees="true">-0.020144144 -0.034890681 0 -45 2 240</pose>
        <geometry>
          <mesh>
            <uri>models://mecanum_wheel_left/meshes/mecanum_wheel_roller.stl</uri>
          </mesh>
        </geometry>
        <material>
          <ambient>0.5 0.5 0.5</ambient>
          <diffuse>0.5 0.5 0.5</diffuse>
          <specular>0.1 0.1 0.1</specular>
        </material>
      </visual>

      <visual name="roller_8_visual">
        <pose degrees="true">0.006995988 -0.039676218 0 -45 2 280</pose>
        <geometry>
          <mesh>
            <uri>models://mecanum_wheel_left/meshes/mecanum_wheel_roller.stl</uri>
          </mesh>
        </geometry>
        <material>
          <ambient>0.5 0.5 0.5</ambient>
          <diffuse>0.5 0.5 0.5</diffuse>
          <specular>0.1 0.1 0.1</specular>
        </material>
      </visual>

      <visual name="roller_9_visual">
        <pose degrees="true">0.030862619 -0.025896812 0 -45 2 320</pose>
        <geometry>
          <mesh>
            <uri>models://mecanum_wheel_left/meshes/mecanum_wheel_roller.stl</uri>
          </mesh>
        </geometry>
        <material>
          <ambient>0.5 0.5 0.5</ambient>
          <diffuse>0.5 0.5 0.5</diffuse>
          <specular>0.1 0.1 0.1</specular>
        </material>
      </visual> -->
    </link>

    <link name="roller_1_link">
      <pose degrees="true">0.040288288 0 0 -45 2 0</pose>
      <inertial>
        <pose>0 0 0 0 0 0</pose>
        <mass>0.015838863</mass>
        <inertia>
          <ixx>2.36316E-06</ixx>
          <ixy>0</ixy>
          <ixz>0</ixz>
          <iyy>2.36316E-06</iyy>
          <iyz>0</iyz>
          <izz>7.66601E-07</izz>
        </inertia>
      </inertial>
      <collision name="collision">
        <pose degrees="true">0 0 0 90 9 0</pose>
        <geometry>
          <sphere>
            <radius>0.011</radius>
          </sphere>
        </geometry>
        <surface>
          <friction>
            <ode>
              <mu>10.0</mu>
              <mu2>10.0</mu2>
            </ode>
          </friction>
        </surface>
      </collision>
      <visual name="visual">
        <pose degrees="true">0 0 0 90 9 0</pose>
        <geometry>
          <ellipsoid>
            <radii>0.011 0.025 0.011</radii>
          </ellipsoid>
        </geometry>
        <material>
          <ambient>0.1 0.1 0.1</ambient>
          <diffuse>0.1 0.1 0.1</diffuse>
          <specular>0.1 0.1 0.1</specular>
        </material>
      </visual>
    </link>
    <joint name="roller_1_joint" type="revolute">
      <child>roller_1_link</child>
      <parent>wheel_link</parent>
      <axis>
        <xyz>0 0 1</xyz>
        <limit>
          <lower>-1.0e16</lower>
          <upper>1.0e16</upper>
        </limit>
        <dynamics>
          <damping>0.0000</damping>
          <friction>0.0001</friction>
        </dynamics>
      </axis>
    </joint>

    <link name="roller_2_link">
      <pose degrees="true">0.030862619 0.025896812 0 -45 2 40</pose>
      <inertial>
        <pose>0 0 0 0 0 0</pose>
        <mass>0.015838863</mass>
        <inertia>
          <ixx>2.36316E-06</ixx>
          <ixy>0</ixy>
          <ixz>0</ixz>
          <iyy>2.36316E-06</iyy>
          <iyz>0</iyz>
          <izz>7.66601E-07</izz>
        </inertia>
      </inertial>
      <collision name="collision">
        <pose degrees="true">0 0 0 90 9 0</pose>
        <geometry>
          <sphere>
            <radius>0.011</radius>
          </sphere>
        </geometry>
        <surface>
          <friction>
            <ode>
              <mu>10.0</mu>
              <mu2>10.0</mu2>
            </ode>
          </friction>
        </surface>
      </collision>
      <visual name="visual">
        <pose degrees="true">0 0 0 90 9 0</pose>
        <geometry>
          <ellipsoid>
            <radii>0.011 0.025 0.011</radii>
          </ellipsoid>
        </geometry>
        <material>
          <ambient>0.1 0.1 0.1</ambient>
          <diffuse>0.1 0.1 0.1</diffuse>
          <specular>0.1 0.1 0.1</specular>
        </material>
      </visual>
    </link>
    <joint name="roller_2_joint" type="revolute">
      <child>roller_2_link</child>
      <parent>wheel_link</parent>
      <axis>
        <xyz>0 0 1</xyz>
        <limit>
          <lower>-1.0e16</lower>
          <upper>1.0e16</upper>
        </limit>
        <dynamics>
          <damping>0.0000</damping>
          <friction>0.0001</friction>
        </dynamics>
      </axis>
    </joint>

    <link name="roller_3_link">
      <pose degrees="true">0.006995988 0.039676218 0 -45 2 80</pose>
      <inertial>
        <pose>0 0 0 0 0 0</pose>
        <mass>0.015838863</mass>
        <inertia>
          <ixx>2.36316E-06</ixx>
          <ixy>0</ixy>
          <ixz>0</ixz>
          <iyy>2.36316E-06</iyy>
          <iyz>0</iyz>
          <izz>7.66601E-07</izz>
        </inertia>
      </inertial>
      <collision name="collision">
        <pose degrees="true">0 0 0 90 9 0</pose>
        <geometry>
          <sphere>
            <radius>0.011</radius>
          </sphere>
        </geometry>
        <surface>
          <friction>
            <ode>
              <mu>10.0</mu>
              <mu2>10.0</mu2>
            </ode>
          </friction>
        </surface>
      </collision>
      <visual name="visual">
        <pose degrees="true">0 0 0 90 9 0</pose>
        <geometry>
          <ellipsoid>
            <radii>0.011 0.025 0.011</radii>
          </ellipsoid>
        </geometry>
        <material>
          <ambient>0.1 0.1 0.1</ambient>
          <diffuse>0.1 0.1 0.1</diffuse>
          <specular>0.1 0.1 0.1</specular>
        </material>
      </visual>
    </link>
    <joint name="roller_3_joint" type="revolute">
      <child>roller_3_link</child>
      <parent>wheel_link</parent>
      <axis>
        <xyz>0 0 1</xyz>
        <limit>
          <lower>-1.0e16</lower>
          <upper>1.0e16</upper>
        </limit>
        <dynamics>
          <damping>0.0000</damping>
          <friction>0.0001</friction>
        </dynamics>
      </axis>
    </joint>

    <link name="roller_4_link">
      <pose degrees="true">-0.020144144 0.034890681 0 -45 2 120</pose>
      <inertial>
        <pose>0 0 0 0 0 0</pose>
        <mass>0.015838863</mass>
        <inertia>
          <ixx>2.36316E-06</ixx>
          <ixy>0</ixy>
          <ixz>0</ixz>
          <iyy>2.36316E-06</iyy>
          <iyz>0</iyz>
          <izz>7.66601E-07</izz>
        </inertia>
      </inertial>
      <collision name="collision">
        <pose degrees="true">0 0 0 90 9 0</pose>
        <geometry>
          <sphere>
            <radius>0.011</radius>
          </sphere>
        </geometry>
        <surface>
          <friction>
            <ode>
              <mu>10.0</mu>
              <mu2>10.0</mu2>
            </ode>
          </friction>
        </surface>
      </collision>
      <visual name="visual">
        <pose degrees="true">0 0 0 90 9 0</pose>
        <geometry>
          <ellipsoid>
            <radii>0.011 0.025 0.011</radii>
          </ellipsoid>
        </geometry>
        <material>
          <ambient>0.1 0.1 0.1</ambient>
          <diffuse>0.1 0.1 0.1</diffuse>
          <specular>0.1 0.1 0.1</specular>
        </material>
      </visual>
    </link>
    <joint name="roller_4_joint" type="revolute">
      <child>roller_4_link</child>
      <parent>wheel_link</parent>
      <axis>
        <xyz>0 0 1</xyz>
        <limit>
          <lower>-1.0e16</lower>
          <upper>1.0e16</upper>
        </limit>
        <dynamics>
          <damping>0.0000</damping>
          <friction>0.0001</friction>
        </dynamics>
      </axis>
    </joint>

    <link name="roller_5_link">
      <pose degrees="true">-0.037858607 0.013779406 0 -45 2 160</pose>
      <inertial>
        <pose>0 0 0 0 0 0</pose>
        <mass>0.015838863</mass>
        <inertia>
          <ixx>2.36316E-06</ixx>
          <ixy>0</ixy>
          <ixz>0</ixz>
          <iyy>2.36316E-06</iyy>
          <iyz>0</iyz>
          <izz>7.66601E-07</izz>
        </inertia>
      </inertial>
      <collision name="collision">
        <pose degrees="true">0 0 0 90 9 0</pose>
        <geometry>
          <sphere>
            <radius>0.011</radius>
          </sphere>
        </geometry>
        <surface>
          <friction>
            <ode>
              <mu>10.0</mu>
              <mu2>10.0</mu2>
            </ode>
          </friction>
        </surface>
      </collision>
      <visual name="visual">
        <pose degrees="true">0 0 0 90 9 0</pose>
        <geometry>
          <ellipsoid>
            <radii>0.011 0.025 0.011</radii>
          </ellipsoid>
        </geometry>
        <material>
          <ambient>0.1 0.1 0.1</ambient>
          <diffuse>0.1 0.1 0.1</diffuse>
          <specular>0.1 0.1 0.1</specular>
        </material>
      </visual>
    </link>
    <joint name="roller_5_joint" type="revolute">
      <child>roller_5_link</child>
      <parent>wheel_link</parent>
      <axis>
        <xyz>0 0 1</xyz>
        <limit>
          <lower>-1.0e16</lower>
          <upper>1.0e16</upper>
        </limit>
        <dynamics>
          <damping>0.0000</damping>
          <friction>0.0001</friction>
        </dynamics>
      </axis>
    </joint>

    <link name="roller_6_link">
      <pose degrees="true">-0.037858607 -0.013779406 0 -45 2 200</pose>
      <inertial>
        <pose>0 0 0 0 0 0</pose>
        <mass>0.015838863</mass>
        <inertia>
          <ixx>2.36316E-06</ixx>
          <ixy>0</ixy>
          <ixz>0</ixz>
          <iyy>2.36316E-06</iyy>
          <iyz>0</iyz>
          <izz>7.66601E-07</izz>
        </inertia>
      </inertial>
      <collision name="collision">
        <pose degrees="true">0 0 0 90 9 0</pose>
        <geometry>
          <sphere>
            <radius>0.011</radius>
          </sphere>
        </geometry>
        <surface>
          <friction>
            <ode>
              <mu>10.0</mu>
              <mu2>10.0</mu2>
            </ode>
          </friction>
        </surface>
      </collision>
      <visual name="visual">
        <pose degrees="true">0 0 0 90 9 0</pose>
        <geometry>
          <ellipsoid>
            <radii>0.011 0.025 0.011</radii>
          </ellipsoid>
        </geometry>
        <material>
          <ambient>0.1 0.1 0.1</ambient>
          <diffuse>0.1 0.1 0.1</diffuse>
          <specular>0.1 0.1 0.1</specular>
        </material>
      </visual>
    </link>
    <joint name="roller_6_joint" type="revolute">
      <child>roller_6_link</child>
      <parent>wheel_link</parent>
      <axis>
        <xyz>0 0 1</xyz>
        <limit>
          <lower>-1.0e16</lower>
          <upper>1.0e16</upper>
        </limit>
        <dynamics>
          <damping>0.0000</damping>
          <friction>0.0001</friction>
        </dynamics>
      </axis>
    </joint>

    <link name="roller_7_link">
      <pose degrees="true">-0.020144144 -0.034890681 0 -45 2 240</pose>
      <inertial>
        <pose>0 0 0 0 0 0</pose>
        <mass>0.015838863</mass>
        <inertia>
          <ixx>2.36316E-06</ixx>
          <ixy>0</ixy>
          <ixz>0</ixz>
          <iyy>2.36316E-06</iyy>
          <iyz>0</iyz>
          <izz>7.66601E-07</izz>
        </inertia>
      </inertial>
      <collision name="collision">
        <pose degrees="true">0 0 0 90 9 0</pose>
        <geometry>
          <sphere>
            <radius>0.011</radius>
          </sphere>
        </geometry>
        <surface>
          <friction>
            <ode>
              <mu>10.0</mu>
              <mu2>10.0</mu2>
            </ode>
          </friction>
        </surface>
      </collision>
      <visual name="visual">
        <pose degrees="true">0 0 0 90 9 0</pose>
        <geometry>
          <ellipsoid>
            <radii>0.011 0.025 0.011</radii>
          </ellipsoid>
        </geometry>
        <material>
          <ambient>0.1 0.1 0.1</ambient>
          <diffuse>0.1 0.1 0.1</diffuse>
          <specular>0.1 0.1 0.1</specular>
        </material>
      </visual>
    </link>
    <joint name="roller_7_joint" type="revolute">
      <child>roller_7_link</child>
      <parent>wheel_link</parent>
      <axis>
        <xyz>0 0 1</xyz>
        <limit>
          <lower>-1.0e16</lower>
          <upper>1.0e16</upper>
        </limit>
        <dynamics>
          <damping>0.0000</damping>
          <friction>0.0001</friction>
        </dynamics>
      </axis>
    </joint>

    <link name="roller_8_link">
      <pose degrees="true">0.006995988 -0.039676218 0 -45 2 280</pose>
      <inertial>
        <pose>0 0 0 0 0 0</pose>
        <mass>0.015838863</mass>
        <inertia>
          <ixx>2.36316E-06</ixx>
          <ixy>0</ixy>
          <ixz>0</ixz>
          <iyy>2.36316E-06</iyy>
          <iyz>0</iyz>
          <izz>7.66601E-07</izz>
        </inertia>
      </inertial>
      <collision name="collision">
        <pose degrees="true">0 0 0 90 9 0</pose>
        <geometry>
          <sphere>
            <radius>0.011</radius>
          </sphere>
        </geometry>
        <surface>
          <friction>
            <ode>
              <mu>10.0</mu>
              <mu2>10.0</mu2>
            </ode>
          </friction>
        </surface>
      </collision>
      <visual name="visual">
        <pose degrees="true">0 0 0 90 9 0</pose>
        <geometry>
          <ellipsoid>
            <radii>0.011 0.025 0.011</radii>
          </ellipsoid>
        </geometry>
        <material>
          <ambient>0.1 0.1 0.1</ambient>
          <diffuse>0.1 0.1 0.1</diffuse>
          <specular>0.1 0.1 0.1</specular>
        </material>
      </visual>
    </link>
    <joint name="roller_8_joint" type="revolute">
      <child>roller_8_link</child>
      <parent>wheel_link</parent>
      <axis>
        <xyz>0 0 1</xyz>
        <limit>
          <lower>-1.0e16</lower>
          <upper>1.0e16</upper>
        </limit>
        <dynamics>
          <damping>0.0000</damping>
          <friction>0.0001</friction>
        </dynamics>
      </axis>
    </joint>

    <link name="roller_9_link">
      <pose degrees="true">0.030862619 -0.025896812 0 -45 2 320</pose>
      <inertial>
        <pose>0 0 0 0 0 0</pose>
        <mass>0.015838863</mass>
        <inertia>
          <ixx>2.36316E-06</ixx>
          <ixy>0</ixy>
          <ixz>0</ixz>
          <iyy>2.36316E-06</iyy>
          <iyz>0</iyz>
          <izz>7.66601E-07</izz>
        </inertia>
      </inertial>
      <collision name="collision">
        <pose degrees="true">0 0 0 90 9 0</pose>
        <geometry>
          <sphere>
            <radius>0.011</radius>
          </sphere>
        </geometry>
        <surface>
          <friction>
            <ode>
              <mu>10.0</mu>
              <mu2>10.0</mu2>
            </ode>
          </friction>
        </surface>
      </collision>
      <visual name="visual">
        <pose degrees="true">0 0 0 90 9 0</pose>
        <geometry>
          <ellipsoid>
            <radii>0.011 0.025 0.011</radii>
          </ellipsoid>
        </geometry>
        <material>
          <ambient>0.1 0.1 0.1</ambient>
          <diffuse>0.1 0.1 0.1</diffuse>
          <specular>0.1 0.1 0.1</specular>
        </material>
      </visual>
    </link>
    <joint name="roller_9_joint" type="revolute">
      <child>roller_9_link</child>
      <parent>wheel_link</parent>
      <axis>
        <xyz>0 0 1</xyz>
        <limit>
          <lower>-1.0e16</lower>
          <upper>1.0e16</upper>
        </limit>
        <dynamics>
          <damping>0.0000</damping>
          <friction>0.0001</friction>
        </dynamics>
      </axis>
    </joint>

  </model>
</sdf>