<?xml version='1.0'?>
<sdf version='1.6'>
<model name='daf_xf_450_tractor'>

  <link name='base_link'>
    <inertial>
      <pose>0 0 0 0 0 0</pose>
      <mass>15000</mass>
      <inertia>
        <ixx>8062.625</ixx>
        <ixy>0</ixy>
        <ixz>0</ixz>
        <iyy>44714.5</iyy>
        <iyz>0</iyz>
        <izz>52152.125</izz>
      </inertia>
    </inertial>
    <collision name='chassis_collision'>
      <pose>-0.41 0 0 0 0 0</pose>
      <geometry>
        <box>
          <size>5.96 2.49 0.5</size>
        </box>
      </geometry>
    </collision>
    <collision name='cab_collision'>
      <pose>1.35 0 1.295 0 0 0</pose>
      <geometry>
        <box>
          <size>2.44 2.49 2.09</size>
        </box>
      </geometry>
    </collision>
    <visual name='chassis_visual'>
      <pose>-0.41 0 0 0 0 0</pose>
      <geometry>
        <mesh>
          <uri>model://daf_xf_450_tractor/meshes/tractor_chassis.dae</uri>
        </mesh>
      </geometry>
      <material>
        <ambient>1 1 1</ambient>
        <diffuse>1 1 1</diffuse>
        <specular>0.1 0.1 0.1</specular>
        <pbr>
          <metal>
            <albedo_map>model://daf_xf_450_tractor/materials/textures/tractor_chassis.png</albedo_map>
            <metalness_map>model://daf_xf_450_tractor/materials/textures/silver_metal/silver_metal_metallic.jpg</metalness_map>
            <normal_map>model://daf_xf_450_tractor/materials/textures/silver_metal/silver_metal_normal.jpg</normal_map>
            <roughness_map>model://daf_xf_450_tractor/materials/textures/silver_metal/silver_metal_roughness.jpg</roughness_map>
            <roughness>0.2</roughness>
            <metalness>0.2</metalness> 
          </metal>
        </pbr>
      </material>
    </visual>
    <!-- <visual name='chassis_visual'>
      <pose>-0.41 0 0 0 0 0</pose>
      <geometry>
        <box>
          <size>5.96 1.59 0.5</size>
        </box>
      </geometry>
      <material>
        <ambient>0 1 0</ambient>
        <diffuse>0 1 0</diffuse>
        <specular>0.1 0.1 0.1 1</specular>
      </material>
    </visual>
    <visual name='cab_visual'>
      <pose>1.35 0 1.295 0 0 0</pose>
      <geometry>
        <box>
          <size>2.44 2.49 2.09</size>
        </box>
      </geometry>
      <material>
        <ambient>0 1 0</ambient>
        <diffuse>0 1 0</diffuse>
        <specular>0.1 0.1 0.1 1</specular>
      </material>
    </visual> -->
  </link>

  <joint name='front_left_steer_joint' type='revolute'>
    <pose relative_to='base_link'>1.2 0.705 -0.4675 0 0 0</pose>
    <parent>base_link</parent>
    <child>front_left_steer_link</child>
    <axis>
      <xyz>0 0 1</xyz>
      <limit>
        <lower>-0.698131701</lower>
        <upper>0.698131701</upper>
      </limit>
      <dynamics>
        <damping>0.0001</damping>
      </dynamics>
    </axis>
  </joint>
  <link name='front_left_steer_link'>
    <pose relative_to='front_left_steer_joint'>0 0 0 0 0 0</pose>
    <inertial>
      <pose>0 0 0 0 0 0</pose>
      <mass>1</mass>
      <inertia>
        <ixx>0.001458333</ixx>
        <ixy>0</ixy>
        <ixz>0</ixz>
        <iyy>0.001458333</iyy>
        <iyz>0</iyz>
        <izz>0.00125</izz>
      </inertia>
    </inertial>
    <collision name='collision'>
      <pose>0 0 0 0 0 0</pose>
      <geometry>
        <cylinder>
          <radius>0.05</radius>
          <length>0.1</length>
        </cylinder>
      </geometry>
    </collision>
    <visual name='visual'>
      <pose>0 0 0 0 0 0</pose>
      <geometry>
        <cylinder>
          <radius>0.05</radius>
          <length>0.1</length>
        </cylinder>
      </geometry>
      <material>
        <ambient>0 0 1</ambient>
        <diffuse>0 0 1</diffuse>
        <specular>0.1 0.1 0.1 1</specular>
      </material>
    </visual>
  </link>

  <joint name='front_left_wheel_joint' type='revolute'>
    <pose relative_to='front_left_steer_link'>0 0.36 0 -1.5708 0 0</pose>
    <parent>front_left_steer_link</parent>
    <child>front_left_wheel_link</child>
    <axis>
      <xyz>0 0 1</xyz>
      <limit>
        <lower>-1e+16</lower>
        <upper>1e+16</upper>
      </limit>
      <dynamics>
        <damping>0.0001</damping>
      </dynamics>
    </axis>
  </joint>
  <link name='front_left_wheel_link'>
    <pose relative_to='front_left_wheel_joint'>0 0 0 0 0 0</pose>
    <inertial>
      <pose>0 0 0 0 0 0</pose>
      <mass>40</mass>
      <inertia>
        <ixx>2.6645625</ixx>
        <ixy>0</ixy>
        <ixz>0</ixz>
        <iyy>2.6645625</iyy>
        <iyz>0</iyz>
        <izz>4.465125</izz>
      </inertia>
    </inertial>
    <collision name='collision'>
      <pose>0 0 0 0 0 0</pose>
      <geometry>
        <cylinder>
          <radius>0.4725</radius>
          <length>0.36</length>
        </cylinder>
      </geometry>
      <surface>
        <friction>
          <ode>
            <mu>1.0</mu>
            <mu2>1.0</mu2>
            <fdir1>1 0 0</fdir1>
            <slip1>0.0</slip1>
            <slip2>0.0</slip2>
          </ode>
        </friction>
      </surface>
    </collision>
    <visual name='tyre_visual'>
      <pose>0 0 0 0 0 0</pose>
      <geometry>
        <mesh>
          <uri>model://daf_xf_450_tractor/meshes/tractor_wheel_tyre_front.dae</uri>
        </mesh>
      </geometry>
      <material>
        <ambient>1 1 1</ambient>
        <diffuse>1 1 1</diffuse>
        <specular>1 1 1</specular>
        <pbr>
          <metal>
            <albedo_map>model://daf_xf_450_tractor/materials/textures/rubber_01/rubber_01_diffuse.jpg</albedo_map>
            <normal_map>model://daf_xf_450_tractor/materials/textures/rubber_01/rubber_01_normal.jpg</normal_map>
            <roughness_map>model://daf_xf_450_tractor/materials/textures/rubber_01/rubber_01_roughness.jpg</roughness_map>
            <roughness>1.0</roughness>
            <metalness>0.0</metalness> 
          </metal>
        </pbr>
      </material>
    </visual>
    <visual name='hub_visual'>
      <pose>0 0 0 0 0 0</pose>
      <geometry>
        <mesh>
          <uri>model://daf_xf_450_tractor/meshes/tractor_wheel_hub_front.dae</uri>
        </mesh>
      </geometry>
        <material>
          <ambient>1 1 1</ambient>
          <diffuse>1 1 1</diffuse>
          <specular>1 1 1</specular>
          <pbr>
            <metal>
              <albedo_map>model://daf_xf_450_tractor/materials/textures/silver_metal/silver_metal_diffuse.jpg</albedo_map>
              <metalness_map>model://daf_xf_450_tractor/materials/textures/silver_metal/silver_metal_metallic.jpg</metalness_map>
              <normal_map>model://daf_xf_450_tractor/materials/textures/silver_metal/silver_metal_normal.jpg</normal_map>
              <roughness_map>model://daf_xf_450_tractor/materials/textures/silver_metal/silver_metal_roughness.jpg</roughness_map>
              <roughness>0.5</roughness>
              <metalness>1.0</metalness> 
            </metal>
          </pbr>
        </material>
    </visual>
    <!-- <visual name='visual'>
      <pose>0 0 0 0 0 0</pose>
      <geometry>
        <cylinder>
          <length>0.36</length>
          <radius>0.4725</radius>
        </cylinder>
      </geometry>
      <material>
        <ambient>1 0 0</ambient>
        <diffuse>1 0 0</diffuse>
        <specular>0.1 0.1 0.1 1</specular>
      </material>
    </visual> -->
  </link>

  <joint name='front_right_steer_joint' type='revolute'>
    <pose relative_to='base_link'>1.2 -0.705 -0.4675 0 0 0</pose>
    <parent>base_link</parent>
    <child>front_right_steer_link</child>
    <axis>
      <xyz>0 0 1</xyz>
      <limit>
        <lower>-0.698131701</lower>
        <upper>0.698131701</upper>
      </limit>
      <dynamics>
        <damping>0.0001</damping>
      </dynamics>
    </axis>
  </joint>
  <link name='front_right_steer_link'>
    <pose relative_to='front_right_steer_joint'>0 0 0 0 0 0</pose>
    <inertial>
      <pose>0 0 0 0 0 0</pose>
      <mass>1</mass>
      <inertia>
        <ixx>0.001458333</ixx>
        <ixy>0</ixy>
        <ixz>0</ixz>
        <iyy>0.001458333</iyy>
        <iyz>0</iyz>
        <izz>0.00125</izz>
      </inertia>
    </inertial>
    <collision name='collision'>
      <pose>0 0 0 0 0 0</pose>
      <geometry>
        <cylinder>
          <radius>0.05</radius>
          <length>0.1</length>
        </cylinder>
      </geometry>
    </collision>
    <visual name='visual'>
      <pose>0 0 0 0 0 0</pose>
      <geometry>
        <cylinder>
          <radius>0.05</radius>
          <length>0.1</length>
        </cylinder>
      </geometry>
      <material>
        <ambient>0 0 1</ambient>
        <diffuse>0 0 1</diffuse>
        <specular>0.1 0.1 0.1 1</specular>
      </material>
    </visual>
  </link>

  <joint name='front_right_wheel_joint' type='revolute'>
    <pose relative_to='front_right_steer_link'>0 -0.36 0 -1.5708 0 0</pose>
    <parent>front_right_steer_link</parent>
    <child>front_right_wheel_link</child>
    <axis>
      <xyz>0 0 1</xyz>
      <limit>
        <lower>-1e+16</lower>
        <upper>1e+16</upper>
      </limit>
      <dynamics>
        <damping>0.0001</damping>
      </dynamics>
    </axis>
  </joint>
  <link name='front_right_wheel_link'>
    <pose relative_to='front_right_wheel_joint'>0 0 0 0 0 0</pose>
    <inertial>
      <pose>0 0 0 0 0 0</pose>
      <mass>40</mass>
      <inertia>
        <ixx>2.6645625</ixx>
        <ixy>0</ixy>
        <ixz>0</ixz>
        <iyy>2.6645625</iyy>
        <iyz>0</iyz>
        <izz>4.465125</izz>
      </inertia>
    </inertial>
    <collision name='collision'>
      <pose>0 0 0 0 0 0</pose>
      <geometry>
        <cylinder>
          <radius>0.4725</radius>
          <length>0.36</length>
        </cylinder>
      </geometry>
      <surface>
        <friction>
          <ode>
            <mu>1.0</mu>
            <mu2>1.0</mu2>
            <fdir1>1 0 0</fdir1>
            <slip1>0.0</slip1>
            <slip2>0.0</slip2>
          </ode>
        </friction>
      </surface>
    </collision>
    <visual name='tyre_visual'>
      <pose>0 0 0 3.14159265 0 0</pose>
      <geometry>
        <mesh>
          <uri>model://daf_xf_450_tractor/meshes/tractor_wheel_tyre_front.dae</uri>
        </mesh>
      </geometry>
      <material>
        <ambient>1 1 1</ambient>
        <diffuse>1 1 1</diffuse>
        <specular>1 1 1</specular>
        <pbr>
          <metal>
            <albedo_map>model://daf_xf_450_tractor/materials/textures/rubber_01/rubber_01_diffuse.jpg</albedo_map>
            <normal_map>model://daf_xf_450_tractor/materials/textures/rubber_01/rubber_01_normal.jpg</normal_map>
            <roughness_map>model://daf_xf_450_tractor/materials/textures/rubber_01/rubber_01_roughness.jpg</roughness_map>
            <roughness>1.0</roughness>
            <metalness>0.0</metalness> 
          </metal>
        </pbr>
      </material>
    </visual>
    <visual name='hub_visual'>
      <pose>0 0 0 3.14159265 0 0</pose>
      <geometry>
        <mesh>
          <uri>model://daf_xf_450_tractor/meshes/tractor_wheel_hub_front.dae</uri>
        </mesh>
      </geometry>
        <material>
          <ambient>1 1 1</ambient>
          <diffuse>1 1 1</diffuse>
          <specular>1 1 1</specular>
          <pbr>
            <metal>
              <albedo_map>model://daf_xf_450_tractor/materials/textures/silver_metal/silver_metal_diffuse.jpg</albedo_map>
              <metalness_map>model://daf_xf_450_tractor/materials/textures/silver_metal/silver_metal_metallic.jpg</metalness_map>
              <normal_map>model://daf_xf_450_tractor/materials/textures/silver_metal/silver_metal_normal.jpg</normal_map>
              <roughness_map>model://daf_xf_450_tractor/materials/textures/silver_metal/silver_metal_roughness.jpg</roughness_map>
              <roughness>0.5</roughness>
              <metalness>1.0</metalness> 
            </metal>
          </pbr>
        </material>
    </visual>
    <!-- <visual name='visual'>
      <pose>0 0 0 0 0 0</pose>
      <geometry>
        <cylinder>
          <length>0.36</length>
          <radius>0.4725</radius>
        </cylinder>
      </geometry>
      <material>
        <ambient>1 0 0</ambient>
        <diffuse>1 0 0</diffuse>
        <specular>0.1 0.1 0.1 1</specular>
      </material>
    </visual> -->
  </link>

  <joint name='rear_left_wheel_joint' type='revolute'>
    <pose relative_to='base_link'>-2.4 1.02 -0.49 -1.5708 0 0</pose>
    <parent>base_link</parent>
    <child>rear_left_wheel_link</child>
    <axis>
      <xyz>0 0 1</xyz>
      <limit>
        <lower>-1e+16</lower>
        <upper>1e+16</upper>
      </limit>
      <dynamics>
        <damping>0.0001</damping>
      </dynamics>
    </axis>
  </joint>
  <link name='rear_left_wheel_link'>
    <pose relative_to='rear_left_wheel_joint'>0 0 0 0 0 0</pose>
    <inertial>
      <pose>0 0 0 0 0 0</pose>
      <mass>40</mass>
      <inertia>
        <ixx>2.7</ixx>
        <ixy>0</ixy>
        <ixz>0</ixz>
        <iyy>2.7</iyy>
        <iyz>0</iyz>
        <izz>4.05</izz>
      </inertia>
    </inertial>
    <collision name='collision'>
      <pose>0 0 0 0 0 0</pose>
      <geometry>
        <cylinder>
          <radius>0.45</radius>
          <length>0.45</length>
        </cylinder>
      </geometry>
      <surface>
        <friction>
          <ode>
            <mu>1.0</mu>
            <mu2>1.0</mu2>
            <fdir1>1 0 0</fdir1>
            <slip1>0.0</slip1>
            <slip2>0.0</slip2>
          </ode>
        </friction>
      </surface>
    </collision>
    <visual name='tyre_visual'>
      <pose>0 0 0 0 0 0</pose>
      <geometry>
        <mesh>
          <uri>model://daf_xf_450_tractor/meshes/tractor_wheel_tyre_rear.dae</uri>
        </mesh>
      </geometry>
      <material>
        <ambient>1 1 1</ambient>
        <diffuse>1 1 1</diffuse>
        <specular>1 1 1</specular>
        <pbr>
          <metal>
            <albedo_map>model://daf_xf_450_tractor/materials/textures/rubber_01/rubber_01_diffuse.jpg</albedo_map>
            <normal_map>model://daf_xf_450_tractor/materials/textures/rubber_01/rubber_01_normal.jpg</normal_map>
            <roughness_map>model://daf_xf_450_tractor/materials/textures/rubber_01/rubber_01_roughness.jpg</roughness_map>
            <roughness>1.0</roughness>
            <metalness>0.0</metalness> 
          </metal>
        </pbr>
      </material>
    </visual>
    <visual name='hub_visual'>
      <pose>0 0 0 0 0 0</pose>
      <geometry>
        <mesh>
          <uri>model://daf_xf_450_tractor/meshes/tractor_wheel_hub_rear.dae</uri>
        </mesh>
      </geometry>
        <material>
          <ambient>1 1 1</ambient>
          <diffuse>1 1 1</diffuse>
          <specular>1 1 1</specular>
          <pbr>
            <metal>
              <albedo_map>model://daf_xf_450_tractor/materials/textures/silver_metal/silver_metal_diffuse.jpg</albedo_map>
              <metalness_map>model://daf_xf_450_tractor/materials/textures/silver_metal/silver_metal_metallic.jpg</metalness_map>
              <normal_map>model://daf_xf_450_tractor/materials/textures/silver_metal/silver_metal_normal.jpg</normal_map>
              <roughness_map>model://daf_xf_450_tractor/materials/textures/silver_metal/silver_metal_roughness.jpg</roughness_map>
              <roughness>0.5</roughness>
              <metalness>1.0</metalness> 
            </metal>
          </pbr>
        </material>
    </visual>
    <!-- <visual name='visual'>
      <pose>0 0 0 0 0 0</pose>
      <geometry>
        <cylinder>
          <length>0.45</length>
          <radius>0.45</radius>
        </cylinder>
      </geometry>
      <material>
          <ambient>1 0 0</ambient>
          <diffuse>1 0 0</diffuse>
          <specular>0.1 0.1 0.1 1</specular>
      </material>
    </visual> -->
  </link>

  <joint name='rear_right_wheel_joint' type='revolute'>
    <pose relative_to='base_link'>-2.4 -1.02 -0.49 -1.5708 0 0</pose>
    <parent>base_link</parent>
    <child>rear_right_wheel_link</child>
    <axis>
      <xyz>0 0 1</xyz>
      <limit>
        <lower>-1e+16</lower>
        <upper>1e+16</upper>
      </limit>
      <dynamics>
        <damping>0.0001</damping>
      </dynamics>
    </axis>
  </joint>
  <link name='rear_right_wheel_link'>
    <pose relative_to='rear_right_wheel_joint'>0 0 0 0 0 0</pose>
    <inertial>
      <pose>0 0 0 0 0 0</pose>
      <mass>40</mass>
      <inertia>
        <ixx>2.7</ixx>
        <ixy>0</ixy>
        <ixz>0</ixz>
        <iyy>2.7</iyy>
        <iyz>0</iyz>
        <izz>4.05</izz>
      </inertia>
    </inertial>
    <collision name='collision'>
      <pose>0 0 0 0 0 0</pose>
      <geometry>
        <cylinder>
          <radius>0.45</radius>
          <length>0.45</length>
        </cylinder>
      </geometry>
      <surface>
        <friction>
          <ode>
            <mu>1.0</mu>
            <mu2>1.0</mu2>
            <fdir1>1 0 0</fdir1>
            <slip1>0.0</slip1>
            <slip2>0.0</slip2>
          </ode>
        </friction>
      </surface>
    </collision>
    <visual name='tyre_visual'>
      <pose>0 0 0 3.14159265 0 0</pose>
      <geometry>
        <mesh>
          <uri>model://daf_xf_450_tractor/meshes/tractor_wheel_tyre_rear.dae</uri>
        </mesh>
      </geometry>
      <material>
        <ambient>1 1 1</ambient>
        <diffuse>1 1 1</diffuse>
        <specular>1 1 1</specular>
        <pbr>
          <metal>
            <albedo_map>model://daf_xf_450_tractor/materials/textures/rubber_01/rubber_01_diffuse.jpg</albedo_map>
            <normal_map>model://daf_xf_450_tractor/materials/textures/rubber_01/rubber_01_normal.jpg</normal_map>
            <roughness_map>model://daf_xf_450_tractor/materials/textures/rubber_01/rubber_01_roughness.jpg</roughness_map>
            <roughness>1.0</roughness>
            <metalness>0.0</metalness> 
          </metal>
        </pbr>
      </material>
    </visual>
    <visual name='hub_visual'>
      <pose>0 0 0 3.14159265 0 0</pose>
      <geometry>
        <mesh>
          <uri>model://daf_xf_450_tractor/meshes/tractor_wheel_hub_rear.dae</uri>
        </mesh>
      </geometry>
        <material>
          <ambient>1 1 1</ambient>
          <diffuse>1 1 1</diffuse>
          <specular>1 1 1</specular>
          <pbr>
            <metal>
              <albedo_map>model://daf_xf_450_tractor/materials/textures/silver_metal/silver_metal_diffuse.jpg</albedo_map>
              <metalness_map>model://daf_xf_450_tractor/materials/textures/silver_metal/silver_metal_metallic.jpg</metalness_map>
              <normal_map>model://daf_xf_450_tractor/materials/textures/silver_metal/silver_metal_normal.jpg</normal_map>
              <roughness_map>model://daf_xf_450_tractor/materials/textures/silver_metal/silver_metal_roughness.jpg</roughness_map>
              <roughness>0.5</roughness>
              <metalness>1.0</metalness> 
            </metal>
          </pbr>
        </material>
    </visual>
    <!-- <visual name='visual'>
      <pose>0 0 0 0 0 0</pose>
      <geometry>
        <cylinder>
          <length>0.45</length>
          <radius>0.45</radius>
        </cylinder>
      </geometry>
      <material>
          <ambient>1 0 0</ambient>
          <diffuse>1 0 0</diffuse>
          <specular>0.1 0.1 0.1 1</specular>
      </material>
    </visual> -->
  </link>

  <!-- Sensors -->
  <link name='imu_link'>
    <inertial>
      <mass>0.01</mass>
      <inertia>
        <ixx>1.66667E-07</ixx>
        <ixy>0</ixy>
        <ixz>0</ixz>
        <iyy>1.66667E-07</iyy>
        <iyz>0</iyz>
        <izz>1.66667E-07</izz>
      </inertia>
    </inertial>
    <sensor name="imu_sensor" type="imu">
      <pose degrees="true">0 0 0 180 0 0</pose>
      <always_on>1</always_on>
      <update_rate>1000.0</update_rate>
    </sensor>
  </link>
  <joint name='imu_joint' type='revolute'>
    <child>imu_link</child>
    <parent>base_link</parent>
    <axis>
      <xyz>0 0 1</xyz>
      <limit>
        <lower>0</lower>
        <upper>0</upper>
      </limit>
      <dynamics>
        <damping>0.0001</damping>
      </dynamics>
      <use_parent_model_frame>1</use_parent_model_frame>
    </axis>
  </joint>

  <!-- Plugins -->
  <plugin name="gz::sim::systems::JointStatePublisher"
      filename="gz-sim-joint-state-publisher-system">
  </plugin>
  <plugin name="gz::sim::systems::ApplyJointForce"
      filename="gz-sim-apply-joint-force-system">
      <joint_name>rear_left_wheel_joint</joint_name>
  </plugin>
  <plugin name="gz::sim::systems::ApplyJointForce"
      filename="gz-sim-apply-joint-force-system">
      <joint_name>rear_right_wheel_joint</joint_name>
  </plugin>
  <plugin name="gz::sim::systems::ApplyJointForce"
      filename="gz-sim-apply-joint-force-system">
      <joint_name>front_left_steer_joint</joint_name>
  </plugin>
  <plugin name="gz::sim::systems::ApplyJointForce"
      filename="gz-sim-apply-joint-force-system">
      <joint_name>front_right_steer_joint</joint_name>
  </plugin>

  <plugin name="ArduPilotPlugin"
      filename="ArduPilotPlugin">
    <!-- Port settings -->
    <fdm_addr>127.0.0.1</fdm_addr>
    <fdm_port_in>9002</fdm_port_in>
    <connectionTimeoutMaxCount>5</connectionTimeoutMaxCount>
    <modelXYZToAirplaneXForwardZDown degrees="true">0 0 0 180 0 0</modelXYZToAirplaneXForwardZDown>
    <gazeboXYZToNED degrees="true">0 0 0 180 0 90</gazeboXYZToNED>

    <!-- Sensors -->
    <!-- <imuName>imu_link::imu_sensor</imuName> -->
    <imuName>imu_sensor</imuName>

    <!-- Control / channels -->

    <!--
        SERVO1_FUNCTION 94 (Script 1)
    -->
    <control channel="0">
      <jointName>rear_left_wheel_joint</jointName>
      <useForce>1</useForce>
      <multiplier>100.0</multiplier>
      <offset>-0.5</offset>
      <servo_min>1000</servo_min>
      <servo_max>2000</servo_max>
      <type>VELOCITY</type>
      <p_gain>1000</p_gain>
      <i_gain>0</i_gain>
      <d_gain>0</d_gain>
      <i_max>1</i_max>
      <i_min>-1</i_min>
      <cmd_max>100000.0</cmd_max>
      <cmd_min>-100000.0</cmd_min>
    </control>

    <!--
        SERVO2_FUNCTION 95 (Script 2)
    -->
    <control channel="1">
      <jointName>rear_right_wheel_joint</jointName>
      <useForce>1</useForce>
      <multiplier>100.0</multiplier>
      <offset>-0.5</offset>
      <servo_min>1000</servo_min>
      <servo_max>2000</servo_max>
      <type>VELOCITY</type>
      <p_gain>1000</p_gain>
      <i_gain>0</i_gain>
      <d_gain>0</d_gain>
      <i_max>1</i_max>
      <i_min>-1</i_min>
      <cmd_max>100000.0</cmd_max>
      <cmd_min>-100000.0</cmd_min>
    </control>

    <!--
        SERVO3_FUNCTION 96 (Script 3)
    -->
    <control channel="2">
      <jointName>front_left_steer_joint</jointName>
      <useForce>1</useForce>
      <multiplier>1.396263402</multiplier>
      <offset>-0.5</offset>
      <servo_min>1000</servo_min>
      <servo_max>2000</servo_max>
      <type>POSITION</type>
      <p_gain>10000.0</p_gain>
      <i_gain>0</i_gain>
      <d_gain>2000</d_gain>
      <i_max>-1</i_max>
      <i_min>0</i_min>
      <cmd_max>10000.0</cmd_max>
      <cmd_min>-10000.0</cmd_min>
    </control>

    <!--
        SERVO4_FUNCTION 97 (Script 4)
    -->
    <control channel="3">
      <jointName>front_right_steer_joint</jointName>
      <useForce>1</useForce>
      <multiplier>1.396263402</multiplier>
      <offset>-0.5</offset>
      <servo_min>1000</servo_min>
      <servo_max>2000</servo_max>
      <type>POSITION</type>
      <p_gain>10000.0</p_gain>
      <i_gain>0</i_gain>
      <d_gain>2000</d_gain>
      <i_max>-1</i_max>
      <i_min>0</i_min>
      <cmd_max>10000.0</cmd_max>
      <cmd_min>-10000.0</cmd_min>
    </control>
  </plugin>

</model>
</sdf>
