<?xml version="1.0"?>
<sdf version="1.9">
  <model name="pik_20b_sailplane">
    <pose>0 0 0 0 0 0</pose>
    <link name="base_link">`
      <inertial>
        <pose>0 0 0.5 0 0 0</pose>
        <mass>300</mass>
        <inertia>
          <ixx>1574.24</ixx>
          <ixy>0</ixy>
          <ixz>0</ixz>
          <iyy>402.54</iyy>
          <iyz>0</iyz>
          <izz>1912.35</izz>
        </inertia>
      </inertial>

      <collision name="fuselage_collision">
        <pose degrees="true">2.155 0 0 0 0 180</pose>
        <geometry>
          <mesh>
            <uri>model://pik_20b_sailplane/meshes/pik_20b_fuselage_collision.stl</uri>
          </mesh>
        </geometry>
      </collision>

      <!-- <collision name="main_wheel_collision">
        <pose degrees="true">2.155 0 0 0 0 180</pose>
        <geometry>
          <mesh>
            <uri>model://pik_20b_sailplane/meshes/pik_20b_main_wheel_collision.stl</uri>
          </mesh>
        </geometry>
      </collision> -->
      <!-- <collision name="tail_wheel_collision">
        <pose degrees="true">2.155 0 0 0 0 180</pose>
        <geometry>
          <mesh>
            <uri>model://pik_20b_sailplane/meshes/pik_20b_tail_wheel_collision.stl</uri>
          </mesh>
        </geometry>
      </collision> -->

      <collision name="left_wing_collision">
        <pose degrees="true">2.155 0 0 0 0 180</pose>
        <geometry>
          <mesh>
            <uri>model://pik_20b_sailplane/meshes/pik_20b_left_wing_collision.stl</uri>
          </mesh>
        </geometry>
      </collision>
      <collision name="right_wing_collision">
        <pose degrees="true">2.155 0 0 0 0 180</pose>
        <geometry>
          <mesh>
            <uri>model://pik_20b_sailplane/meshes/pik_20b_right_wing_collision.stl</uri>
          </mesh>
        </geometry>
      </collision>

      <visual name="fuselage_visual">
        <pose degrees="true">2.155 0 0 0 0 180</pose>
        <geometry>
          <mesh>
            <uri>model://pik_20b_sailplane/meshes/pik_20b_fuselage.dae</uri>
          </mesh>
        </geometry>
      </visual>
      <visual name="left_wheel_door_visual">
        <pose degrees="true">2.155 0 0 0 0 180</pose>
        <geometry>
          <mesh>
            <uri>model://pik_20b_sailplane/meshes/pik_20b_left_wheel_door.dae</uri>
          </mesh>
        </geometry>
      </visual>
      <visual name="right_wheel_door_visual">
        <pose degrees="true">2.155 0 0 0 0 180</pose>
        <geometry>
          <mesh>
            <uri>model://pik_20b_sailplane/meshes/pik_20b_right_wheel_door.dae</uri>
          </mesh>
        </geometry>
      </visual>

      <!-- <visual name="main_wheel_visual">
        <pose degrees="true">2.155 0 0 0 0 180</pose>
        <geometry>
          <mesh>
            <uri>model://pik_20b_sailplane/meshes/pik_20b_main_wheel.dae</uri>
          </mesh>
        </geometry>
      </visual> -->
      <!-- <visual name="tail_wheel_visual">
        <pose degrees="true">2.155 0 0 0 0 180</pose>
        <geometry>
          <mesh>
            <uri>model://pik_20b_sailplane/meshes/pik_20b_tail_wheel.dae</uri>
          </mesh>
        </geometry>
      </visual> -->

      <visual name="left_wing_visual">
        <pose degrees="true">2.155 0 0 0 0 180</pose>
        <geometry>
          <mesh>
            <uri>model://pik_20b_sailplane/meshes/pik_20b_left_wing.dae</uri>
          </mesh>
        </geometry>
      </visual>
      <visual name="right_wing_visual">
        <pose degrees="true">2.155 0 0 0 0 180</pose>
        <geometry>
          <mesh>
            <uri>model://pik_20b_sailplane/meshes/pik_20b_right_wing.dae</uri>
          </mesh>
        </geometry>
      </visual>

      <!-- <visual name="left_flap_visual">
        <pose degrees="true">2.155 0 0 0 0 180</pose>
        <geometry>
          <mesh>
            <uri>model://pik_20b_sailplane/meshes/pik_20b_left_flap.dae</uri>
          </mesh>
        </geometry>
      </visual> -->
      <!-- <visual name="right_flap_visual">
        <pose degrees="true">2.155 0 0 0 0 180</pose>
        <geometry>
          <mesh>
            <uri>model://pik_20b_sailplane/meshes/pik_20b_right_flap.dae</uri>
          </mesh>
        </geometry>
      </visual> -->

      <!-- <visual name="left_aileron_visual">
        <pose degrees="true">2.155 0 0 0 0 180</pose>
        <geometry>
          <mesh>
            <uri>model://pik_20b_sailplane/meshes/pik_20b_left_aileron.dae</uri>
          </mesh>
        </geometry>
      </visual> -->
      <!-- <visual name="right_aileron_visual">
        <pose degrees="true">2.155 0 0 0 0 180</pose>
        <geometry>
          <mesh>
            <uri>model://pik_20b_sailplane/meshes/pik_20b_right_aileron.dae</uri>
          </mesh>
        </geometry>
      </visual> -->

      <!-- <visual name="elevator_visual">
        <pose degrees="true">2.155 0 0 0 0 180</pose>
        <geometry>
          <mesh>
            <uri>model://pik_20b_sailplane/meshes/pik_20b_elevator.dae</uri>
          </mesh>
        </geometry>
      </visual> -->
      <!-- <visual name="rudder_visual">
        <pose degrees="true">2.155 0 0 0 0 180</pose>
        <geometry>
          <mesh>
            <uri>model://pik_20b_sailplane/meshes/pik_20b_rudder.dae</uri>
          </mesh>
        </geometry>
      </visual> -->

      <!-- CP visuals. -->
      <visual name="cp_left_wing_visual">
        <pose degrees="true">-0.03 3.0 0.75 0 0 0</pose>
        <geometry>
          <sphere>
            <radius>0.1</radius>
          </sphere>
        </geometry>
        <material>
          <ambient>1 0 0 1</ambient>
          <diffuse>1 0 0 1</diffuse>
          <specular>0.1 0.1 0.1 1</specular>
        </material>
      </visual>
      <visual name="cp_right_wing_visual">
        <pose degrees="true">-0.03 -3.0 0.75 0 0 0</pose>
        <geometry>
          <sphere>
            <radius>0.1</radius>
          </sphere>
        </geometry>
        <material>
          <ambient>0 1 0 1</ambient>
          <diffuse>0 1 0 1</diffuse>
          <specular>0.1 0.1 0.1 1</specular>
        </material>
      </visual>
      <!-- <visual name="cp_left_flap_visual">
        <pose degrees="true">-0.42 2.5 0.7 0 0 0</pose>
        <geometry>
          <sphere>
            <radius>0.05</radius>
          </sphere>
        </geometry>
        <material>
          <ambient>1 0 1 1</ambient>
          <diffuse>1 0 1 1</diffuse>
          <specular>0.1 0.1 0.1 1</specular>
        </material>
      </visual> -->
      <!-- <visual name="cp_right_flap_visual">
        <pose degrees="true">-0.42 -2.5 0.7 0 0 0</pose>
        <geometry>
          <sphere>
            <radius>0.05</radius>
          </sphere>
        </geometry>
        <material>
          <ambient>1 0 1 1</ambient>
          <diffuse>1 0 1 1</diffuse>
          <specular>0.1 0.1 0.1 1</specular>
        </material>
      </visual> -->
      <!-- <visual name="cp_left_aileron_visual">
        <pose degrees="true">-0.22 6.0 0.875 0 0 0</pose>
        <geometry>
          <sphere>
            <radius>0.05</radius>
          </sphere>
        </geometry>
        <material>
          <ambient>1 0 1 1</ambient>
          <diffuse>1 0 1 1</diffuse>
          <specular>0.1 0.1 0.1 1</specular>
        </material>
      </visual> -->
      <!-- <visual name="cp_right_aileron_visual">
        <pose degrees="true">-0.22 -6.0 0.875 0 0 0</pose>
        <geometry>
          <sphere>
            <radius>0.05</radius>
          </sphere>
        </geometry>
        <material>
          <ambient>1 0 1 1</ambient>
          <diffuse>1 0 1 1</diffuse>
          <specular>0.1 0.1 0.1 1</specular>
        </material>
      </visual> -->
      <visual name="cp_hstab_visual">
        <pose degrees="true">-3.55 0 1.68 0 0 0</pose>
        <geometry>
          <sphere>
            <radius>0.1</radius>
          </sphere>
        </geometry>
        <material>
          <ambient>0 0 1 1</ambient>
          <diffuse>0 0 1 1</diffuse>
          <specular>0.1 0.1 0.1 1</specular>
        </material>
      </visual>
      <!-- <visual name="cp_elevator_visual">
        <pose degrees="true">-3.84 0 1.695 0 0 0</pose>
        <geometry>
          <sphere>
            <radius>0.05</radius>
          </sphere>
        </geometry>
        <material>
          <ambient>1 0 1 1</ambient>
          <diffuse>1 0 1 1</diffuse>
          <specular>0.1 0.1 0.1 1</specular>
        </material>
      </visual> -->
      <visual name="cp_vstab_visual">
        <pose degrees="true">-3.55 0 1.15 0 0 0</pose>
        <geometry>
          <sphere>
            <radius>0.1</radius>
          </sphere>
        </geometry>
        <material>
          <ambient>0 0 1 1</ambient>
          <diffuse>0 0 1 1</diffuse>
          <specular>0.1 0.1 0.1 1</specular>
        </material>
      </visual>
      <!-- <visual name="cp_rudder_visual">
        <pose degrees="true">-3.9 0 1.15 0 0 0</pose>
        <geometry>
          <sphere>
            <radius>0.05</radius>
          </sphere>
        </geometry>
        <material>
          <ambient>1 0 1 1</ambient>
          <diffuse>1 0 1 1</diffuse>
          <specular>0.1 0.1 0.1 1</specular>
        </material>
      </visual> -->

      <!-- Sensors. -->
      <sensor name="imu_sensor" type="imu">
        <pose degrees="true">0 0 0 180 0 0</pose>
        <always_on>1</always_on>
        <update_rate>1000.0</update_rate>
      </sensor>
      <sensor name="navsat_sensor" type="navsat">
        <always_on>1</always_on>
        <update_rate>1</update_rate>
      </sensor>

    </link>

    <link name="main_wheel_link">
      <inertial>
        <pose degrees="true">0.2627999 0 0.065767 0 0 0</pose>
        <mass>5</mass>
        <inertia>
          <ixx>0.044</ixx>
          <ixy>0</ixy>
          <ixz>0</ixz>
          <iyy>0.078</iyy>
          <iyz>0</iyz>
          <izz>0.044</izz>
        </inertia>
      </inertial>
      <visual name="main_wheel_visual">
        <pose degrees="true">2.155 0 0 0 0 180</pose>
        <geometry>
          <mesh>
            <uri>model://pik_20b_sailplane/meshes/pik_20b_main_wheel.dae</uri>
          </mesh>
        </geometry>
      </visual>
      <collision name="main_wheel_collision">
        <pose degrees="true">2.155 0 0 0 0 180</pose>
        <geometry>
          <mesh>
            <uri>model://pik_20b_sailplane/meshes/pik_20b_main_wheel_collision.stl</uri>
          </mesh>
        </geometry>
      </collision>
    </link>
    <joint name="main_wheel_joint" type="revolute">
      <pose>0.2627999 0 0.065767 0 0 0</pose>
      <parent>base_link</parent>
      <child>main_wheel_link</child>
      <axis>
        <xyz>0 1 0</xyz>
        <limit>
          <lower>-1.0e-16</lower>
          <upper>1.0e+16</upper>
        </limit>
        <dynamics>
          <damping>0.0001</damping>
        </dynamics>
      </axis>
    </joint>

    <link name="tail_wheel_link">
      <inertial>
        <pose>-3.6236 0 0.42776 0 0 0</pose>
        <mass>2</mass>
        <inertia>
          <ixx>0.0023</ixx>
          <ixy>0</ixy>
          <ixz>0</ixz>
          <iyy>0.0042</iyy>
          <iyz>0</iyz>
          <izz>0.0023</izz>
        </inertia>
      </inertial>
      <visual name="tail_wheel_visual">
        <pose degrees="true">2.155 0 0 0 0 180</pose>
        <geometry>
          <mesh>
            <uri>model://pik_20b_sailplane/meshes/pik_20b_tail_wheel.dae</uri>
          </mesh>
        </geometry>
      </visual>
      <collision name="main_wheel_collision">
        <pose degrees="true">2.155 0 0 0 0 180</pose>
        <geometry>
          <mesh>
            <uri>model://pik_20b_sailplane/meshes/pik_20b_tail_wheel_collision.stl</uri>
          </mesh>
        </geometry>
      </collision>
    </link>
    <joint name="tail_wheel_joint" type="revolute">
      <pose>-3.6236 0 0.42776 0 0 0</pose>
      <parent>base_link</parent>
      <child>tail_wheel_link</child>
      <axis>
        <xyz>0 1 0</xyz>
        <limit>
          <lower>-1.0e-16</lower>
          <upper>1.0e+16</upper>
        </limit>
        <dynamics>
          <damping>0.0001</damping>
        </dynamics>
      </axis>
    </joint>

    <link name="left_flap_link">
      <inertial>
        <pose>-0.42 2.5 0.7 0 0 0</pose>
        <mass>10</mass>
        <inertia>
          <ixx>13.885</ixx>
          <ixy>0</ixy>
          <ixz>0</ixz>
          <iyy>0.111</iyy>
          <iyz>0</iyz>
          <izz>13.970</izz>
        </inertia>
      </inertial>
      <visual name="left_flap_visual">
        <pose degrees="true">2.155 0 0 0 0 180</pose>
        <geometry>
          <mesh>
            <uri>model://pik_20b_sailplane/meshes/pik_20b_left_flap.dae</uri>
          </mesh>
        </geometry>
      </visual>
      <visual name="cp_left_flap_visual">
        <pose degrees="true">-0.42 2.5 0.7 0 0 0</pose>
        <geometry>
          <sphere>
            <radius>0.05</radius>
          </sphere>
        </geometry>
        <material>
          <ambient>1 0 1 1</ambient>
          <diffuse>1 0 1 1</diffuse>
          <specular>0.1 0.1 0.1 1</specular>
        </material>
      </visual>
      <collision name="left_flap_collision">
        <pose degrees="true">2.155 0 0 0 0 180</pose>
        <geometry>
          <mesh>
            <uri>model://pik_20b_sailplane/meshes/pik_20b_left_flap.dae</uri>
          </mesh>
        </geometry>
      </collision>
    </link>
    <joint name="left_flap_joint" type="revolute">
      <pose degrees="true">-0.2675 4.465 0.8 3.0 0 -2.7</pose>
      <parent>base_link</parent>
      <child>left_flap_link</child>
      <axis>
        <xyz>0 1 0</xyz>
        <limit>
          <lower>-1.396263</lower>
          <upper>0.139626</upper>
        </limit>
        <dynamics>
          <damping>0.0001</damping>
        </dynamics>
      </axis>
    </joint>

    <link name="right_flap_link">
      <inertial>
        <pose>-0.42 -2.5 0.7 0 0 0</pose>
        <mass>10</mass>
        <inertia>
          <ixx>13.885</ixx>
          <ixy>0</ixy>
          <ixz>0</ixz>
          <iyy>0.111</iyy>
          <iyz>0</iyz>
          <izz>13.970</izz>
        </inertia>
      </inertial>
      <visual name="right_flap_visual">
        <pose degrees="true">2.155 0 0 0 0 180</pose>
        <geometry>
          <mesh>
            <uri>model://pik_20b_sailplane/meshes/pik_20b_right_flap.dae</uri>
          </mesh>
        </geometry>
      </visual>
      <visual name="cp_right_flap_visual">
        <pose degrees="true">-0.42 -2.5 0.7 0 0 0</pose>
        <geometry>
          <sphere>
            <radius>0.05</radius>
          </sphere>
        </geometry>
        <material>
          <ambient>1 0 1 1</ambient>
          <diffuse>1 0 1 1</diffuse>
          <specular>0.1 0.1 0.1 1</specular>
        </material>
      </visual>
      <collision name="right_flap_collision">
        <pose degrees="true">2.155 0 0 0 0 180</pose>
        <geometry>
          <mesh>
            <uri>model://pik_20b_sailplane/meshes/pik_20b_right_flap.dae</uri>
          </mesh>
        </geometry>
      </collision>
    </link>
    <joint name="right_flap_joint" type="revolute">
      <pose degrees="true">-0.2675 -4.465 0.8 -3.0 0 2.7</pose>
      <parent>base_link</parent>
      <child>right_flap_link</child>
      <axis>
        <xyz>0 1 0</xyz>
        <limit>
          <lower>-1.396263</lower>
          <upper>0.139626</upper>
        </limit>
        <dynamics>
          <damping>0.0001</damping>
        </dynamics>
      </axis>
    </joint>

    <link name="left_aileron_link">
      <inertial>
        <pose>-0.22 6.0 0.875 0 0 0</pose>
        <mass>10</mass>
        <inertia>
          <ixx>6.446</ixx>
          <ixy>0</ixy>
          <ixz>0</ixz>
          <iyy>0.0651</iyy>
          <iyz>0</iyz>
          <izz>6.500</izz>
        </inertia>
      </inertial>
      <visual name="left_aileron_visual">
        <pose degrees="true">2.155 0 0 0 0 180</pose>
        <geometry>
          <mesh>
            <uri>model://pik_20b_sailplane/meshes/pik_20b_left_aileron.dae</uri>
          </mesh>
        </geometry>
      </visual>
      <visual name="cp_left_aileron_visual">
        <pose degrees="true">-0.22 6.0 0.875 0 0 0</pose>
        <geometry>
          <sphere>
            <radius>0.05</radius>
          </sphere>
        </geometry>
        <material>
          <ambient>1 0 1 1</ambient>
          <diffuse>1 0 1 1</diffuse>
          <specular>0.1 0.1 0.1 1</specular>
        </material>
      </visual>
      <collision name="left_aileron_collision">
        <pose degrees="true">2.155 0 0 0 0 180</pose>
        <geometry>
          <mesh>
            <uri>model://pik_20b_sailplane/meshes/pik_20b_left_aileron.dae</uri>
          </mesh>
        </geometry>
      </collision>
    </link>
    <joint name="left_aileron_joint" type="revolute">
      <pose degrees="true">-0.2675 4.465 0.8 3.0 0 -3.0</pose>
      <parent>base_link</parent>
      <child>left_aileron_link</child>
      <axis>
        <xyz>0 1 0</xyz>
        <limit>
          <lower>-0.366519</lower>
          <upper>0.418879</upper>
        </limit>
        <dynamics>
          <damping>0.0001</damping>
        </dynamics>
      </axis>
    </joint>

    <link name="right_aileron_link">
      <inertial>
        <pose>-0.22 -6.0 0.875 0 0 0</pose>
        <mass>10</mass>
        <inertia>
          <ixx>6.446</ixx>
          <ixy>0</ixy>
          <ixz>0</ixz>
          <iyy>0.0651</iyy>
          <iyz>0</iyz>
          <izz>6.500</izz>
        </inertia>
      </inertial>
      <visual name="right_aileron_visual">
        <pose degrees="true">2.155 0 0 0 0 180</pose>
        <geometry>
          <mesh>
            <uri>model://pik_20b_sailplane/meshes/pik_20b_right_aileron.dae</uri>
          </mesh>
        </geometry>
      </visual>
      <visual name="cp_right_aileron_visual">
        <pose degrees="true">-0.22 -6.0 0.875 0 0 0</pose>
        <geometry>
          <sphere>
            <radius>0.05</radius>
          </sphere>
        </geometry>
        <material>
          <ambient>1 0 1 1</ambient>
          <diffuse>1 0 1 1</diffuse>
          <specular>0.1 0.1 0.1 1</specular>
        </material>
      </visual>
      <collision name="left_aileron_collision">
        <pose degrees="true">2.155 0 0 0 0 180</pose>
        <geometry>
          <mesh>
            <uri>model://pik_20b_sailplane/meshes/pik_20b_right_aileron.dae</uri>
          </mesh>
        </geometry>
      </collision>
    </link>
    <joint name="right_aileron_joint" type="revolute">
      <pose degrees="true">-0.2675 -4.465 0.8 -3.0 0 3.0</pose>
      <parent>base_link</parent>
      <child>right_aileron_link</child>
      <axis>
        <xyz>0 1 0</xyz>
        <limit>
          <lower>-0.366519</lower>
          <upper>0.418879</upper>
        </limit>
        <dynamics>
          <damping>0.0001</damping>
        </dynamics>
      </axis>
    </joint>

    <link name="rudder_link">
      <inertial>
        <pose>-3.9 0 1.15 0 0 0</pose>
        <mass>10</mass>
        <inertia>
          <ixx>1.21</ixx>
          <ixy>0</ixy>
          <ixz>0</ixz>
          <iyy>1.30</iyy>
          <iyz>0</iyz>
          <izz>0.1065</izz>
        </inertia>
      </inertial>
      <visual name="rudder_visual">
        <pose degrees="true">2.155 0 0 0 0 180</pose>
        <geometry>
          <mesh>
            <uri>model://pik_20b_sailplane/meshes/pik_20b_rudder.dae</uri>
          </mesh>
        </geometry>
      </visual>
      <visual name="cp_rudder_visual">
        <pose degrees="true">-3.9 0 1.15 0 0 0</pose>
        <geometry>
          <sphere>
            <radius>0.05</radius>
          </sphere>
        </geometry>
        <material>
          <ambient>1 0 1 1</ambient>
          <diffuse>1 0 1 1</diffuse>
          <specular>0.1 0.1 0.1 1</specular>
        </material>
      </visual>
      <collision name="rudder_collision">
        <pose degrees="true">2.155 0 0 0 0 180</pose>
        <geometry>
          <mesh>
            <uri>model://pik_20b_sailplane/meshes/pik_20b_rudder.dae</uri>
          </mesh>
        </geometry>
      </collision>
    </link>
    <joint name="rudder_joint" type="revolute">
      <pose>-3.8286 0 0.475 0 0 0</pose>
      <parent>base_link</parent>
      <child>rudder_link</child>
      <axis>
        <xyz>0 0 1</xyz>
        <limit>
          <lower>-0.4712389</lower>
          <upper>0.4712389</upper>
        </limit>
        <dynamics>
          <damping>0.0001</damping>
        </dynamics>
      </axis>
    </joint>

    <link name="elevator_link">
      <inertial>
        <pose>-3.84 0 1.695 0 0 0</pose>
        <mass>10</mass>
        <inertia>
          <ixx>3.5023</ixx>
          <ixy>0</ixy>
          <ixz>0</ixz>
          <iyy>0.0145</iyy>
          <iyz>0</iyz>
          <izz>3.5164</izz>
        </inertia>
      </inertial>
      <visual name="elevator_visual">
        <pose degrees="true">2.155 0 0 0 0 180</pose>
        <geometry>
          <mesh>
            <uri>model://pik_20b_sailplane/meshes/pik_20b_elevator.dae</uri>
          </mesh>
        </geometry>
      </visual>
      <visual name="cp_elevator_visual">
        <pose degrees="true">-3.84 0 1.695 0 0 0</pose>
        <geometry>
          <sphere>
            <radius>0.05</radius>
          </sphere>
        </geometry>
        <material>
          <ambient>1 0 1 1</ambient>
          <diffuse>1 0 1 1</diffuse>
          <specular>0.1 0.1 0.1 1</specular>
        </material>
      </visual>
      <collision name="elevator_collision">
        <pose degrees="true">2.155 0 0 0 0 180</pose>
        <geometry>
          <mesh>
            <uri>model://pik_20b_sailplane/meshes/pik_20b_elevator.dae</uri>
          </mesh>
        </geometry>
      </collision>
    </link>
    <joint name="elevator_joint" type="revolute">
      <pose>-3.803 0 1.693 0 0 0</pose>
      <parent>base_link</parent>
      <child>elevator_link</child>
      <axis>
        <xyz>0 1 0</xyz>
        <limit>
          <lower>-0.3490659</lower>
          <upper>0.3490659</upper>
        </limit>
        <dynamics>
          <damping>0.0001</damping>
        </dynamics>
      </axis>
    </joint>

    <link name="engine_link">
      <pose degrees="true">-0.15 0 1.6 0 90 0</pose>
      <inertial>
        <mass>5</mass>
        <inertia>
          <ixx>0.01</ixx>
          <ixy>0</ixy>
          <ixz>0</ixz>
          <iyy>0.01</iyy>
          <iyz>0</iyz>
          <izz>0.01</izz>
        </inertia>
      </inertial>
      <visual name="engine_visual">
        <geometry>
          <cylinder>
            <radius>0.1</radius>
            <length>0.3</length>
          </cylinder>
        </geometry>
        <material>
          <ambient>0.5 0.5 0.5 1</ambient>
          <diffuse>0.5 0.5 0.5 1</diffuse>
          <specular>0.01 0.01 0.01 1</specular>
        </material>
      </visual>
      <collision name="engine_collision">
        <geometry>
          <cylinder>
            <radius>0.1</radius>
            <length>0.3</length>
          </cylinder>
        </geometry>
      </collision>
    </link>
    <joint name="engine_joint" type="revolute">
      <pose>0 0 0 0 0 0</pose>
      <parent>base_link</parent>
      <child>engine_link</child>
      <axis>
        <xyz>0 0 1</xyz>
        <limit>
          <lower>0.0</lower>
          <upper>0.0</upper>
        </limit>
        <dynamics>
          <damping>1.0</damping>
        </dynamics>
      </axis>
    </joint>

    <link name="propeller_link">
      <pose degrees="true">0.05 0 1.6 0 90 0</pose>
      <inertial>
        <mass>5</mass>
        <inertia>
          <ixx>0.01</ixx>
          <ixy>0</ixy>
          <ixz>0</ixz>
          <iyy>0.01</iyy>
          <iyz>0</iyz>
          <izz>0.01</izz>
        </inertia>
      </inertial>
      <visual name="propeller_visual">
        <geometry>
          <box>
            <size>1.270 0.1 0.04</size>
          </box>
        </geometry>
        <material>
          <ambient>0.5 0.5 0.5 1</ambient>
          <diffuse>0.5 0.5 0.5 1</diffuse>
          <specular>0.01 0.01 0.01 1</specular>
        </material>
      </visual>
      <collision name="propeller_collision">
        <geometry>
          <cylinder>
            <radius>0.635</radius>
            <length>0.04</length>
          </cylinder>
        </geometry>
      </collision>
    </link>
    <joint name="propeller_joint" type="revolute">
      <pose>0 0 0 0 0 0</pose>
      <parent>engine_link</parent>
      <child>propeller_link</child>
      <axis>
        <xyz>0 0 1</xyz>
        <limit>
          <lower>-1.0e-16</lower>
          <upper>1.0e+16</upper>
        </limit>
        <dynamics>
          <damping>1.0</damping>
        </dynamics>
      </axis>
    </joint>

    <!-- System plugins. -->
    <plugin filename="gz-sim-joint-state-publisher-system"
      name="gz::sim::systems::JointStatePublisher">
    </plugin>

    <!-- Positive is up. -->
    <plugin
      filename="gz-sim-joint-position-controller-system"
      name="gz::sim::systems::JointPositionController">
      <joint_name>left_flap_joint</joint_name>
      <initial_position>0.0</initial_position>
      <topic>/left_flap_joint/cmd_pos</topic>
      <p_gain>20</p_gain>
      <i_gain>0</i_gain>
      <d_gain>5</d_gain>
      <i_max>1</i_max>
      <i_min>-1</i_min>
      <cmd_max>1000</cmd_max>
      <cmd_min>-1000</cmd_min>
    </plugin>

    <!-- Positive is up. -->
    <plugin
      filename="gz-sim-joint-position-controller-system"
      name="gz::sim::systems::JointPositionController">
      <joint_name>right_flap_joint</joint_name>
      <initial_position>0.0</initial_position>
      <topic>/right_flap_joint/cmd_pos</topic>
      <p_gain>20</p_gain>
      <i_gain>0</i_gain>
      <d_gain>5</d_gain>
      <i_max>1</i_max>
      <i_min>-1</i_min>
      <cmd_max>1000</cmd_max>
      <cmd_min>-1000</cmd_min>
    </plugin>

    <!-- Positive is up. -->
    <plugin
      filename="gz-sim-joint-position-controller-system"
      name="gz::sim::systems::JointPositionController">
      <joint_name>left_aileron_joint</joint_name>
      <initial_position>0.0</initial_position>
      <topic>/left_aileron_joint/cmd_pos</topic>
      <p_gain>20</p_gain>
      <i_gain>0</i_gain>
      <d_gain>5</d_gain>
      <i_max>1</i_max>
      <i_min>-1</i_min>
      <cmd_max>1000</cmd_max>
      <cmd_min>-1000</cmd_min>
    </plugin>

    <!-- Positive is up. -->
    <plugin
      filename="gz-sim-joint-position-controller-system"
      name="gz::sim::systems::JointPositionController">
      <joint_name>right_aileron_joint</joint_name>
      <initial_position>0.0</initial_position>
      <topic>/right_aileron_joint/cmd_pos</topic>
      <p_gain>20</p_gain>
      <i_gain>0</i_gain>
      <d_gain>5</d_gain>
      <i_max>1</i_max>
      <i_min>-1</i_min>
      <cmd_max>1000</cmd_max>
      <cmd_min>-1000</cmd_min>
    </plugin>

    <!-- Positive is right. -->
    <plugin
      filename="gz-sim-joint-position-controller-system"
      name="gz::sim::systems::JointPositionController">
      <joint_name>rudder_joint</joint_name>
      <initial_position>0.0</initial_position>
      <topic>/rudder_joint/cmd_pos</topic>
      <p_gain>20</p_gain>
      <i_gain>0</i_gain>
      <d_gain>5</d_gain>
      <i_max>1</i_max>
      <i_min>-1</i_min>
      <cmd_max>1000</cmd_max>
      <cmd_min>-1000</cmd_min>
    </plugin>

    <!-- Positive is up. -->
    <plugin
      filename="gz-sim-joint-position-controller-system"
      name="gz::sim::systems::JointPositionController">
      <joint_name>elevator_joint</joint_name>
      <initial_position>0.0</initial_position>
      <topic>/elevator_joint/cmd_pos</topic>
      <p_gain>20</p_gain>
      <i_gain>0</i_gain>
      <d_gain>5</d_gain>
      <i_max>1</i_max>
      <i_min>-1</i_min>
      <cmd_max>1000</cmd_max>
      <cmd_min>-1000</cmd_min>
    </plugin>

    <!-- Positive is forward. -->
    <plugin
      filename="gz-sim-thruster-system"
      name="gz::sim::systems::Thruster">
      <namespace>pik_20b_sailplane</namespace>
      <joint_name>propeller_joint</joint_name>
      <thrust_coefficient>0.005</thrust_coefficient>
      <fluid_density>1.2041</fluid_density>
      <propeller_diameter>1.270</propeller_diameter>
      <use_angvel_cmd>1</use_angvel_cmd>
      <max_thrust_cmd>1000.0</max_thrust_cmd>
      <min_thrust_cmd>0.0</min_thrust_cmd>
    </plugin>

    <!-- left wing -->
    <plugin filename="gz-sim-lift-drag-system"
        name="gz::sim::systems::LiftDrag">
      <a0>0.13</a0>
      <cla>3.7</cla>
      <cda>0.06417112299</cda>
      <cma>-1.8</cma>
      <alpha_stall>0.3391428111</alpha_stall>
      <cla_stall>-3.85</cla_stall>
      <cda_stall>-0.9233984055</cda_stall>
      <cma_stall>0</cma_stall>
      <cp>-0.03 3.0 0.75</cp>
      <area>5.0</area>
      <air_density>1.2041</air_density>
      <forward>1 0 0</forward>
      <upward>0 0 1</upward>
      <link_name>base_link</link_name>
    </plugin>

    <!-- right wing -->
    <plugin filename="gz-sim-lift-drag-system"
        name="gz::sim::systems::LiftDrag">
      <a0>0.13</a0>
      <cla>3.7</cla>
      <cda>0.06417112299</cda>
      <cma>-1.8</cma>
      <alpha_stall>0.3391428111</alpha_stall>
      <cla_stall>-3.85</cla_stall>
      <cda_stall>-0.9233984055</cda_stall>
      <cma_stall>0</cma_stall>
      <cp>-0.03 -3.0 0.75</cp>
      <area>5.0</area>
      <air_density>1.2041</air_density>
      <forward>1 0 0</forward>
      <upward>0 0 1</upward>
      <link_name>base_link</link_name>
    </plugin>

    <!-- left_flap -->
    <plugin filename="gz-sim-lift-drag-system"
        name="gz::sim::systems::LiftDrag">
      <a0>0.15</a0>
      <cla>6.8</cla>
      <cda>0.06417112299</cda>
      <cma>-1.8</cma>
      <alpha_stall>0.6391428111</alpha_stall>
      <cla_stall>-3.85</cla_stall>
      <cda_stall>-0.9233984055</cda_stall>
      <cma_stall>0</cma_stall>
      <cp>-0.42 2.5 0.7</cp>
      <area>0.10</area>
      <air_density>1.2041</air_density>
      <forward>1 0 0</forward>
      <upward>0 0 1</upward>
      <link_name>base_link</link_name>
      <control_joint_name>left_flap_joint</control_joint_name>
      <control_joint_rad_to_cl>-5.0</control_joint_rad_to_cl>
    </plugin>

    <!-- right_flap -->
    <plugin filename="gz-sim-lift-drag-system"
        name="gz::sim::systems::LiftDrag">
      <a0>0.15</a0>
      <cla>6.8</cla>
      <cda>0.06417112299</cda>
      <cma>-1.8</cma>
      <alpha_stall>0.6391428111</alpha_stall>
      <cla_stall>-3.85</cla_stall>
      <cda_stall>-0.9233984055</cda_stall>
      <cma_stall>0</cma_stall>
      <cp>-0.42 -2.5 0.7</cp>
      <area>0.10</area>
      <air_density>1.2041</air_density>
      <forward>1 0 0</forward>
      <upward>0 0 1</upward>
      <link_name>base_link</link_name>
      <control_joint_name>right_flap_joint</control_joint_name>
      <control_joint_rad_to_cl>-5.0</control_joint_rad_to_cl>
    </plugin>

    <!-- left_aileron -->
    <plugin filename="gz-sim-lift-drag-system"
        name="gz::sim::systems::LiftDrag">
      <a0>0.15</a0>
      <cla>6.8</cla>
      <cda>0.06417112299</cda>
      <cma>-1.8</cma>
      <alpha_stall>0.6391428111</alpha_stall>
      <cla_stall>-3.85</cla_stall>
      <cda_stall>-0.9233984055</cda_stall>
      <cma_stall>0</cma_stall>
      <cp>-0.22 6.0 0.875</cp>
      <area>0.10</area>
      <air_density>1.2041</air_density>
      <forward>1 0 0</forward>
      <upward>0 0 1</upward>
      <link_name>base_link</link_name>
      <control_joint_name>left_aileron_joint</control_joint_name>
      <control_joint_rad_to_cl>-5.0</control_joint_rad_to_cl>
    </plugin>

    <!-- right_aileron -->
    <plugin filename="gz-sim-lift-drag-system"
        name="gz::sim::systems::LiftDrag">
      <a0>0.15</a0>
      <cla>6.8</cla>
      <cda>0.06417112299</cda>
      <cma>-1.8</cma>
      <alpha_stall>0.6391428111</alpha_stall>
      <cla_stall>-3.85</cla_stall>
      <cda_stall>-0.9233984055</cda_stall>
      <cma_stall>0</cma_stall>
      <cp>-0.22 -6.0 0.875</cp>
      <area>0.10</area>
      <air_density>1.2041</air_density>
      <forward>1 0 0</forward>
      <upward>0 0 1</upward>
      <link_name>base_link</link_name>
      <control_joint_name>right_aileron_joint</control_joint_name>
      <control_joint_rad_to_cl>-5.0</control_joint_rad_to_cl>
    </plugin>

    <!-- horizontal stabiliser -->
    <plugin filename="gz-sim-lift-drag-system"
        name="gz::sim::systems::LiftDrag">
      <a0>0.13</a0>
      <cla>3.7</cla>
      <cda>0.06417112299</cda>
      <cma>-1.8</cma>
      <alpha_stall>0.3391428111</alpha_stall>
      <cla_stall>-3.85</cla_stall>
      <cda_stall>-0.9233984055</cda_stall>
      <cma_stall>0</cma_stall>
      <cp>-3.55 0 1.68</cp>
      <area>1.25</area>
      <air_density>1.2041</air_density>
      <forward>1 0 0</forward>
      <upward>0 0 1</upward>
      <link_name>base_link</link_name>
    </plugin>

    <!-- elevator -->
    <plugin filename="gz-sim-lift-drag-system"
        name="gz::sim::systems::LiftDrag">
      <a0>0.15</a0>
      <cla>6.8</cla>
      <cda>0.06417112299</cda>
      <cma>-1.8</cma>
      <alpha_stall>0.6391428111</alpha_stall>
      <cla_stall>-3.85</cla_stall>
      <cda_stall>-0.9233984055</cda_stall>
      <cma_stall>0</cma_stall>
      <cp>-3.84 0 1.695</cp>
      <area>0.10</area>
      <air_density>1.2041</air_density>
      <forward>1 0 0</forward>
      <upward>0 0 1</upward>
      <link_name>base_link</link_name>
      <control_joint_name>elevator_joint</control_joint_name>
      <control_joint_rad_to_cl>-5.0</control_joint_rad_to_cl>
    </plugin>

    <!-- vertical stabiliser -->
    <plugin filename="gz-sim-lift-drag-system"
        name="gz::sim::systems::LiftDrag">
      <a0>0.13</a0>
      <cla>3.7</cla>
      <cda>0.06417112299</cda>
      <cma>-1.8</cma>
      <alpha_stall>0.3391428111</alpha_stall>
      <cla_stall>-3.85</cla_stall>
      <cda_stall>-0.9233984055</cda_stall>
      <cma_stall>0</cma_stall>
      <cp>-3.55 0 1.15</cp>
      <area>1.02</area>
      <air_density>1.2041</air_density>
      <forward>1 0 0</forward>
      <upward>0 1 0</upward>
      <link_name>base_link</link_name>
    </plugin>

    <!-- rudder -->
    <plugin filename="gz-sim-lift-drag-system"
        name="gz::sim::systems::LiftDrag">
      <a0>0.15</a0>
      <cla>6.8</cla>
      <cda>0.06417112299</cda>
      <cma>-1.8</cma>
      <alpha_stall>0.6391428111</alpha_stall>
      <cla_stall>-3.85</cla_stall>
      <cda_stall>-0.9233984055</cda_stall>
      <cma_stall>0</cma_stall>
      <cp>-3.9 0 1.15</cp>
      <area>0.10</area>
      <air_density>1.2041</air_density>
      <forward>1 0 0</forward>
      <upward>0 1 0</upward>
      <link_name>base_link</link_name>
      <control_joint_name>rudder_joint</control_joint_name>
      <control_joint_rad_to_cl>-5.0</control_joint_rad_to_cl>
    </plugin>

  </model>
</sdf>

