<?xml version="1.0"?>
<sdf version="1.9">
  <model name="pik_20b_sailplane">
    <pose>0 0 0 0 0 0</pose>
    <link name="base_link">`
      <inertial>
        <pose>0 0 0.5 0 0 0</pose>
        <mass>400</mass>
        <inertia>
          <ixx>4.0</ixx>
          <ixy>0</ixy>
          <ixz>0</ixz>
          <iyy>4.0</iyy>
          <iyz>0</iyz>
          <izz>4.0</izz>
        </inertia>
      </inertial>
      <collision name="fuselage_collision">
        <pose degrees="true">2.155 0 0 0 0 180</pose>
        <geometry>
          <mesh>
            <uri>model://pik_20b_sailplane/meshes/pik_20b_fuselage_collision.stl</uri>
          </mesh>
        </geometry>
      </collision>
      <!-- <collision name="main_wheel_collision">
        <pose degrees="true">2.155 0 0 0 0 180</pose>
        <geometry>
          <mesh>
            <uri>model://pik_20b_sailplane/meshes/pik_20b_main_wheel_collision.stl</uri>
          </mesh>
        </geometry>
      </collision> -->
      <!-- <collision name="tail_wheel_collision">
        <pose degrees="true">2.155 0 0 0 0 180</pose>
        <geometry>
          <mesh>
            <uri>model://pik_20b_sailplane/meshes/pik_20b_tail_wheel_collision.stl</uri>
          </mesh>
        </geometry>
      </collision> -->

      <collision name="left_wing_collision">
        <pose degrees="true">2.155 0 0 0 0 180</pose>
        <geometry>
          <mesh>
            <uri>model://pik_20b_sailplane/meshes/pik_20b_left_wing_collision.stl</uri>
          </mesh>
        </geometry>
      </collision>
      <collision name="right_wing_collision">
        <pose degrees="true">2.155 0 0 0 0 180</pose>
        <geometry>
          <mesh>
            <uri>model://pik_20b_sailplane/meshes/pik_20b_right_wing_collision.stl</uri>
          </mesh>
        </geometry>
      </collision>

      <visual name="fuselage_visual">
        <pose degrees="true">2.155 0 0 0 0 180</pose>
        <geometry>
          <mesh>
            <uri>model://pik_20b_sailplane/meshes/pik_20b_fuselage.dae</uri>
          </mesh>
        </geometry>
      </visual>
      <visual name="left_wheel_door_visual">
        <pose degrees="true">2.155 0 0 0 0 180</pose>
        <geometry>
          <mesh>
            <uri>model://pik_20b_sailplane/meshes/pik_20b_left_wheel_door.dae</uri>
          </mesh>
        </geometry>
      </visual>
      <visual name="right_wheel_door_visual">
        <pose degrees="true">2.155 0 0 0 0 180</pose>
        <geometry>
          <mesh>
            <uri>model://pik_20b_sailplane/meshes/pik_20b_right_wheel_door.dae</uri>
          </mesh>
        </geometry>
      </visual>

      <!-- <visual name="main_wheel_visual">
        <pose degrees="true">2.155 0 0 0 0 180</pose>
        <geometry>
          <mesh>
            <uri>model://pik_20b_sailplane/meshes/pik_20b_main_wheel.dae</uri>
          </mesh>
        </geometry>
      </visual> -->
      <!-- <visual name="tail_wheel_visual">
        <pose degrees="true">2.155 0 0 0 0 180</pose>
        <geometry>
          <mesh>
            <uri>model://pik_20b_sailplane/meshes/pik_20b_tail_wheel.dae</uri>
          </mesh>
        </geometry>
      </visual> -->

      <visual name="left_wing_visual">
        <pose degrees="true">2.155 0 0 0 0 180</pose>
        <geometry>
          <mesh>
            <uri>model://pik_20b_sailplane/meshes/pik_20b_left_wing.dae</uri>
          </mesh>
        </geometry>
      </visual>
      <visual name="right_wing_visual">
        <pose degrees="true">2.155 0 0 0 0 180</pose>
        <geometry>
          <mesh>
            <uri>model://pik_20b_sailplane/meshes/pik_20b_right_wing.dae</uri>
          </mesh>
        </geometry>
      </visual>

      <visual name="left_flap_visual">
        <pose degrees="true">2.155 0 0 0 0 180</pose>
        <geometry>
          <mesh>
            <uri>model://pik_20b_sailplane/meshes/pik_20b_left_flap.dae</uri>
          </mesh>
        </geometry>
      </visual>
      <visual name="right_flap_visual">
        <pose degrees="true">2.155 0 0 0 0 180</pose>
        <geometry>
          <mesh>
            <uri>model://pik_20b_sailplane/meshes/pik_20b_right_flap.dae</uri>
          </mesh>
        </geometry>
      </visual>

      <!-- <visual name="left_aileron_visual">
        <pose degrees="true">2.155 0 0 0 0 180</pose>
        <geometry>
          <mesh>
            <uri>model://pik_20b_sailplane/meshes/pik_20b_left_aileron.dae</uri>
          </mesh>
        </geometry>
      </visual> -->
      <!-- <visual name="right_aileron_visual">
        <pose degrees="true">2.155 0 0 0 0 180</pose>
        <geometry>
          <mesh>
            <uri>model://pik_20b_sailplane/meshes/pik_20b_right_aileron.dae</uri>
          </mesh>
        </geometry>
      </visual> -->

      <!-- <visual name="elevator_visual">
        <pose degrees="true">2.155 0 0 0 0 180</pose>
        <geometry>
          <mesh>
            <uri>model://pik_20b_sailplane/meshes/pik_20b_elevator.dae</uri>
          </mesh>
        </geometry>
      </visual> -->
      <!-- <visual name="rudder_visual">
        <pose degrees="true">2.155 0 0 0 0 180</pose>
        <geometry>
          <mesh>
            <uri>model://pik_20b_sailplane/meshes/pik_20b_rudder.dae</uri>
          </mesh>
        </geometry>
      </visual> -->
    </link>

    <link name="main_wheel_link">
      <inertial>
        <pose degrees="true">0.2627999 0 0.065767 0 0 0</pose>
        <mass>5</mass>
        <inertia>
          <ixx>0.01</ixx>
          <ixy>0</ixy>
          <ixz>0</ixz>
          <iyy>0.01</iyy>
          <iyz>0</iyz>
          <izz>0.01</izz>
        </inertia>
      </inertial>
      <visual name="main_wheel_visual">
        <pose degrees="true">2.155 0 0 0 0 180</pose>
        <geometry>
          <mesh>
            <uri>model://pik_20b_sailplane/meshes/pik_20b_main_wheel.dae</uri>
          </mesh>
        </geometry>
      </visual>
      <collision name="main_wheel_collision">
        <pose degrees="true">2.155 0 0 0 0 180</pose>
        <geometry>
          <mesh>
            <uri>model://pik_20b_sailplane/meshes/pik_20b_main_wheel_collision.stl</uri>
          </mesh>
        </geometry>
      </collision>
    </link>
    <joint name="main_wheel_joint" type="revolute">
      <pose>0.2627999 0 0.065767 0 0 0</pose>
      <parent>base_link</parent>
      <child>main_wheel_link</child>
      <axis>
        <xyz>0 1 0</xyz>
        <limit>
          <lower>-1.0e-16</lower>
          <upper>1.0e+16</upper>
        </limit>
        <dynamics>
          <damping>0.0001</damping>
        </dynamics>
      </axis>
    </joint>

    <link name="tail_wheel_link">
      <inertial>
        <pose>-3.6236 0 0.42776 0 0 0</pose>
        <mass>5</mass>
        <inertia>
          <ixx>0.01</ixx>
          <ixy>0</ixy>
          <ixz>0</ixz>
          <iyy>0.01</iyy>
          <iyz>0</iyz>
          <izz>0.01</izz>
        </inertia>
      </inertial>
      <visual name="tail_wheel_visual">
        <pose degrees="true">2.155 0 0 0 0 180</pose>
        <geometry>
          <mesh>
            <uri>model://pik_20b_sailplane/meshes/pik_20b_tail_wheel.dae</uri>
          </mesh>
        </geometry>
      </visual>
      <collision name="main_wheel_collision">
        <pose degrees="true">2.155 0 0 0 0 180</pose>
        <geometry>
          <mesh>
            <uri>model://pik_20b_sailplane/meshes/pik_20b_tail_wheel_collision.stl</uri>
          </mesh>
        </geometry>
      </collision>
    </link>
    <joint name="tail_wheel_joint" type="revolute">
      <pose>-3.6236 0 0.42776 0 0 0</pose>
      <parent>base_link</parent>
      <child>tail_wheel_link</child>
      <axis>
        <xyz>0 1 0</xyz>
        <limit>
          <lower>-1.0e-16</lower>
          <upper>1.0e+16</upper>
        </limit>
        <dynamics>
          <damping>0.0001</damping>
        </dynamics>
      </axis>
    </joint>

    <link name="left_aileron_link">
      <inertial>
        <pose>-0.2675 4.465 0.8 0 0 0</pose>
        <mass>5</mass>
        <inertia>
          <ixx>0.01</ixx>
          <ixy>0</ixy>
          <ixz>0</ixz>
          <iyy>0.01</iyy>
          <iyz>0</iyz>
          <izz>0.01</izz>
        </inertia>
      </inertial>
      <visual name="left_aileron_visual">
        <pose degrees="true">2.155 0 0 0 0 180</pose>
        <geometry>
          <mesh>
            <uri>model://pik_20b_sailplane/meshes/pik_20b_left_aileron.dae</uri>
          </mesh>
        </geometry>
      </visual>
      <collision name="left_aileron_collision">
        <pose degrees="true">2.155 0 0 0 0 180</pose>
        <geometry>
          <mesh>
            <uri>model://pik_20b_sailplane/meshes/pik_20b_left_aileron.dae</uri>
          </mesh>
        </geometry>
      </collision>
    </link>
    <joint name="left_aileron_joint" type="revolute">
      <pose degrees="true">-0.2675 4.465 0.8 3.0 0 -3.0</pose>
      <parent>base_link</parent>
      <child>left_aileron_link</child>
      <axis>
        <xyz>0 1 0</xyz>
        <limit>
          <lower>-0.366519</lower>
          <upper>0.418879</upper>
        </limit>
        <dynamics>
          <damping>0.0001</damping>
        </dynamics>
      </axis>
    </joint>

    <link name="right_aileron_link">
      <inertial>
        <pose>-0.2675 -4.465 0.8 0 0 0</pose>
        <mass>5</mass>
        <inertia>
          <ixx>0.01</ixx>
          <ixy>0</ixy>
          <ixz>0</ixz>
          <iyy>0.01</iyy>
          <iyz>0</iyz>
          <izz>0.01</izz>
        </inertia>
      </inertial>
      <visual name="right_aileron_visual">
        <pose degrees="true">2.155 0 0 0 0 180</pose>
        <geometry>
          <mesh>
            <uri>model://pik_20b_sailplane/meshes/pik_20b_right_aileron.dae</uri>
          </mesh>
        </geometry>
      </visual>
      <collision name="left_aileron_collision">
        <pose degrees="true">2.155 0 0 0 0 180</pose>
        <geometry>
          <mesh>
            <uri>model://pik_20b_sailplane/meshes/pik_20b_right_aileron.dae</uri>
          </mesh>
        </geometry>
      </collision>
    </link>
    <joint name="right_aileron_joint" type="revolute">
      <pose degrees="true">-0.2675 -4.465 0.8 -3.0 0 3.0</pose>
      <parent>base_link</parent>
      <child>right_aileron_link</child>
      <axis>
        <xyz>0 1 0</xyz>
        <limit>
          <lower>-0.366519</lower>
          <upper>0.418879</upper>
        </limit>
        <dynamics>
          <damping>0.0001</damping>
        </dynamics>
      </axis>
    </joint>



    <link name="rudder_link">
      <inertial>
        <pose>-3.8286 0 0.475 0 0 0</pose>
        <mass>5</mass>
        <inertia>
          <ixx>0.01</ixx>
          <ixy>0</ixy>
          <ixz>0</ixz>
          <iyy>0.01</iyy>
          <iyz>0</iyz>
          <izz>0.01</izz>
        </inertia>
      </inertial>
      <visual name="rudder_visual">
        <pose degrees="true">2.155 0 0 0 0 180</pose>
        <geometry>
          <mesh>
            <uri>model://pik_20b_sailplane/meshes/pik_20b_rudder.dae</uri>
          </mesh>
        </geometry>
      </visual>
      <collision name="rudder_collision">
        <pose degrees="true">2.155 0 0 0 0 180</pose>
        <geometry>
          <mesh>
            <uri>model://pik_20b_sailplane/meshes/pik_20b_rudder.dae</uri>
          </mesh>
        </geometry>
      </collision>
    </link>
    <joint name="rudder_joint" type="revolute">
      <pose>-3.8286 0 0.475 0 0 0</pose>
      <parent>base_link</parent>
      <child>rudder_link</child>
      <axis>
        <xyz>0 0 1</xyz>
        <limit>
          <lower>-0.4712389</lower>
          <upper>0.4712389</upper>
        </limit>
        <dynamics>
          <damping>0.0001</damping>
        </dynamics>
      </axis>
    </joint>

    <link name="elevator_link">
      <inertial>
        <pose>-3.803 0 1.693 0 0 0</pose>
        <mass>5</mass>
        <inertia>
          <ixx>0.01</ixx>
          <ixy>0</ixy>
          <ixz>0</ixz>
          <iyy>0.01</iyy>
          <iyz>0</iyz>
          <izz>0.01</izz>
        </inertia>
      </inertial>
      <visual name="elevator_visual">
        <pose degrees="true">2.155 0 0 0 0 180</pose>
        <geometry>
          <mesh>
            <uri>model://pik_20b_sailplane/meshes/pik_20b_elevator.dae</uri>
          </mesh>
        </geometry>
      </visual>
      <collision name="elevator_collision">
        <pose degrees="true">2.155 0 0 0 0 180</pose>
        <geometry>
          <mesh>
            <uri>model://pik_20b_sailplane/meshes/pik_20b_elevator.dae</uri>
          </mesh>
        </geometry>
      </collision>
    </link>
    <joint name="elevator_joint" type="revolute">
      <pose>-3.803 0 1.693 0 0 0</pose>
      <parent>base_link</parent>
      <child>elevator_link</child>
      <axis>
        <xyz>0 1 0</xyz>
        <limit>
          <lower>-0.3490659</lower>
          <upper>0.3490659</upper>
        </limit>
        <dynamics>
          <damping>0.0001</damping>
        </dynamics>
      </axis>
    </joint>

    <link name="engine_link">
      <pose degrees="true">-0.15 0 1.6 0 90 0</pose>
      <inertial>
        <mass>5</mass>
        <inertia>
          <ixx>0.01</ixx>
          <ixy>0</ixy>
          <ixz>0</ixz>
          <iyy>0.01</iyy>
          <iyz>0</iyz>
          <izz>0.01</izz>
        </inertia>
      </inertial>
      <visual name="engine_visual">
        <geometry>
          <cylinder>
            <radius>0.1</radius>
            <length>0.3</length>
          </cylinder>
        </geometry>
        <material>
          <ambient>0.5 0.5 0.5 1</ambient>
          <diffuse>0.5 0.5 0.5 1</diffuse>
          <specular>0.01 0.01 0.01 1</specular>
        </material>
      </visual>
      <collision name="engine_collision">
        <geometry>
          <cylinder>
            <radius>0.1</radius>
            <length>0.3</length>
          </cylinder>
        </geometry>
      </collision>
    </link>
    <joint name="engine_joint" type="revolute">
      <pose>0 0 0 0 0 0</pose>
      <parent>base_link</parent>
      <child>engine_link</child>
      <axis>
        <xyz>0 0 1</xyz>
        <limit>
          <lower>0.0</lower>
          <upper>0.0</upper>
        </limit>
        <dynamics>
          <damping>1.0</damping>
        </dynamics>
      </axis>
    </joint>

    <link name="propeller_link">
      <pose degrees="true">0.05 0 1.6 0 90 0</pose>
      <inertial>
        <mass>5</mass>
        <inertia>
          <ixx>0.01</ixx>
          <ixy>0</ixy>
          <ixz>0</ixz>
          <iyy>0.01</iyy>
          <iyz>0</iyz>
          <izz>0.01</izz>
        </inertia>
      </inertial>
      <visual name="propeller_visual">
        <geometry>
          <box>
            <size>1.270 0.1 0.04</size>
          </box>
        </geometry>
        <material>
          <ambient>0.5 0.5 0.5 1</ambient>
          <diffuse>0.5 0.5 0.5 1</diffuse>
          <specular>0.01 0.01 0.01 1</specular>
        </material>
      </visual>
      <collision name="propeller_collision">
        <geometry>
          <cylinder>
            <radius>0.635</radius>
            <length>0.04</length>
          </cylinder>
        </geometry>
      </collision>
    </link>
    <joint name="propeller_joint" type="revolute">
      <pose>0 0 0 0 0 0</pose>
      <parent>engine_link</parent>
      <child>propeller_link</child>
      <axis>
        <xyz>0 0 1</xyz>
        <limit>
          <lower>-1.0e-16</lower>
          <upper>1.0e+16</upper>
        </limit>
        <dynamics>
          <damping>1.0</damping>
        </dynamics>
      </axis>
    </joint>

    <!-- Positive is right. -->
    <plugin
      filename="gz-sim-joint-position-controller-system"
      name="gz::sim::systems::JointPositionController">
      <joint_name>rudder_joint</joint_name>
      <initial_position>0.0</initial_position>
      <p_gain>0.2</p_gain>
    </plugin>

    <!-- Positive is up. -->
    <plugin
      filename="gz-sim-joint-position-controller-system"
      name="gz::sim::systems::JointPositionController">
      <joint_name>elevator_joint</joint_name>
      <initial_position>0.0</initial_position>
      <p_gain>0.2</p_gain>
    </plugin>

    <!-- Positive is up. -->
    <plugin
      filename="gz-sim-joint-position-controller-system"
      name="gz::sim::systems::JointPositionController">
      <joint_name>left_aileron_joint</joint_name>
      <initial_position>0.0</initial_position>
      <p_gain>0.2</p_gain>
    </plugin>

    <!-- Positive is up. -->
    <plugin
      filename="gz-sim-joint-position-controller-system"
      name="gz::sim::systems::JointPositionController">
      <joint_name>right_aileron_joint</joint_name>
      <initial_position>0.0</initial_position>
      <p_gain>0.2</p_gain>
    </plugin>

    <!-- Positive is forward. -->
    <plugin
      filename="gz-sim-thruster-system"
      name="gz::sim::systems::Thruster">
      <namespace>pik_20b_sailplane</namespace>
      <joint_name>propeller_joint</joint_name>
      <thrust_coefficient>0.005</thrust_coefficient>
      <fluid_density>1.293</fluid_density>
      <propeller_diameter>1.270</propeller_diameter>
    </plugin>

  </model>
</sdf>

