<?xml version='1.0'?>
<sdf version='1.7'>
  <model name='sawppy'>
    <pose>0 0 0.21 0 0 0</pose>
    <link name='base_link'>
      <inertial>
        <pose>0 0 0 0 0 0</pose>
        <mass>1.01</mass>
        <inertia>
          <ixx>0.00748967</ixx>
          <ixy>0</ixy>
          <ixz>0</ixz>
          <iyy>0.015773</iyy>
          <iyz>0</iyz>
          <izz>0.021821</izz>
        </inertia>
      </inertial>
      <collision name='base_link_collision'>
        <pose>0 0 0 0 0 0</pose>
        <geometry>
          <box>
            <size>0.01 0.01 0.01</size>
          </box>
        </geometry>
        <surface>
          <contact>
            <ode/>
          </contact>
          <friction>
            <ode/>
          </friction>
        </surface>
      </collision>
      <collision name='base_link_fixed_joint_lump__body_box_link_collision_1'>
        <pose>0 0 0 0 0 0</pose>
        <geometry>
          <box>
            <size>0.425 0.285 0.093</size>
          </box>
        </geometry>
        <surface>
          <contact>
            <ode/>
          </contact>
          <friction>
            <ode/>
          </friction>
        </surface>
      </collision>
      <visual name='base_link_visual'>
        <pose>0 0 0 0 0 0</pose>
        <geometry>
          <box>
            <size>0.01 0.01 0.01</size>
          </box>
        </geometry>
        <material>
          <ambient>1 0.5088 0.0468 1</ambient>
          <diffuse>1 0.5088 0.0468 1</diffuse>
          <specular>0.5 0.5 0.5 1</specular>
        </material>
      </visual>
      <visual name='base_link_fixed_joint_lump__body_box_link_visual_1'>
        <pose>0 0 0 0 0 0</pose>
        <geometry>
          <mesh>
            <scale>1 1 1</scale>
            <uri>model://sawppy/meshes/bases/body_box.stl</uri>
          </mesh>
        </geometry>
        <material>
          <ambient>0.175 0.175 0.175 1</ambient>
          <diffuse>0.175 0.175 0.175 1</diffuse>
          <specular>0.175 0.175 0.175 1</specular>
        </material>
      </visual>
      <velocity_decay/>
      <gravity>1</gravity>
      <velocity_decay/>
    </link>
    <joint name='diff_brace_joint' type='revolute'>
      <pose relative_to='base_link'>0 0 0.0681 0 0 0</pose>
      <parent>base_link</parent>
      <child>diff_brace_link</child>
      <axis>
        <xyz>0 0 1</xyz>
        <limit>
          <lower>-0.785398</lower>
          <upper>0.785398</upper>
          <effort>100</effort>
          <velocity>100</velocity>
        </limit>
        <dynamics>
          <spring_reference>0</spring_reference>
          <spring_stiffness>0</spring_stiffness>
          <damping>0.1</damping>
          <friction>0.1</friction>
        </dynamics>
      </axis>
      <physics>
        <provide_feedback>1</provide_feedback>
        <ode>
          <implicit_spring_damper>1</implicit_spring_damper>
          <cfm_damping>1</cfm_damping>
          <limit>
            <cfm>0</cfm>
            <erp>0.2</erp>
          </limit>
        </ode>
      </physics>
    </joint>
    <link name='diff_brace_link'>
      <pose relative_to='diff_brace_joint'>0 0 0 0 0 0</pose>
      <inertial>
        <pose degrees="true">0 0 0 0 0 90</pose>
        <mass>0.1</mass>
        <inertia>
          <ixx>3.75e-06</ixx>
          <ixy>0</ixy>
          <ixz>0</ixz>
          <iyy>0.000335208</iyy>
          <iyz>0</iyz>
          <izz>0.000335208</izz>
        </inertia>
      </inertial>
      <collision name='diff_brace_link_collision'>
        <pose degrees="true">0 0 0 0 0 90</pose>
        <geometry>
          <box>
            <size>0.2 0.015 0.015</size>
          </box>
        </geometry>
        <surface>
          <contact>
            <ode/>
          </contact>
          <friction>
            <ode/>
          </friction>
        </surface>
      </collision>
      <visual name='diff_brace_link_visual'>
        <pose>0 0 0 0 0 0</pose>
        <geometry>
          <mesh>
            <scale>1 1 1</scale>
            <uri>model://sawppy/meshes/bases/differential.stl</uri>
          </mesh>
        </geometry>
        <material>
          <ambient>0.175 0.175 0.175 1</ambient>
          <diffuse>0.175 0.175 0.175 1</diffuse>
          <specular>0.175 0.175 0.175 1</specular>
        </material>
      </visual>
      <gravity>1</gravity>
      <velocity_decay/>
    </link>
    <joint name='laser_joint' type='fixed'>
      <pose relative_to='base_link'>0.152 0.078 0.05 0 0 0</pose>
      <parent>base_link</parent>
      <child>laser</child>
      <axis>
        <dynamics>
          <spring_reference>0</spring_reference>
          <spring_stiffness>0</spring_stiffness>
        </dynamics>
        <xyz>0 0 1</xyz>
        <limit>
          <lower>-1e+16</lower>
          <upper>1e+16</upper>
        </limit>
      </axis>
      <physics>
        <ode>
          <limit>
            <cfm>0</cfm>
            <erp>0.2</erp>
          </limit>
        </ode>
      </physics>
    </joint>
    <link name='laser'>
      <pose relative_to='laser_joint'>0 0 0 0 0 0</pose>
      <inertial>
        <pose>0 0 0 0 0 0</pose>
        <mass>0.15</mass>
        <inertia>
          <ixx>9.09375e-05</ixx>
          <ixy>0</ixy>
          <ixz>0</ixz>
          <iyy>9.09375e-05</iyy>
          <iyz>0</iyz>
          <izz>9.1875e-05</izz>
        </inertia>
      </inertial>
      <collision name='laser_collision'>
        <pose>0 0 0 0 0 0</pose>
        <geometry>
          <cylinder>
            <length>0.06</length>
            <radius>0.035</radius>
          </cylinder>
        </geometry>
        <surface>
          <contact>
            <ode/>
          </contact>
          <friction>
            <ode/>
          </friction>
        </surface>
      </collision>
      <visual name='laser_visual'>
        <pose>0 0 0 0 0 0</pose>
        <geometry>
          <mesh>
            <scale>1 1 1</scale>
            <uri>model://sawppy/meshes/sensors/rplidar_a1_assembly_low.stl</uri>
          </mesh>
        </geometry>
        <material>
          <ambient>0.05 0.05 0.05 1</ambient>
          <diffuse>0.05 0.05 0.05 1</diffuse>
          <specular>0.001 0.001 0.001 1</specular>
        </material>
      </visual>
      <gravity>1</gravity>
      <velocity_decay/>
      <!-- <sensor name='laser_sensor' type='gpu_ray'>
        <always_on>1</always_on>
        <update_rate>5</update_rate>
        <visualize>0</visualize>
        <topic>sensors/laser</topic>
        <pose>0 0 0.045 0 0 0</pose>
        <ray>
          <scan>
            <horizontal>
              <samples>360</samples>
              <resolution>1</resolution>
              <min_angle>-3.14159</min_angle>
              <max_angle>3.14159</max_angle>
            </horizontal>
            <vertical>
              <samples>1</samples>
              <resolution>1</resolution>
              <min_angle>0</min_angle>
              <max_angle>0</max_angle>
            </vertical>
          </scan>
          <range>
            <min>0.1</min>
            <max>12</max>
            <resolution>0.05</resolution>
          </range>
          <noise>
            <type>gaussian</type>
            <mean>0</mean>
            <stddev>0.01</stddev>
          </noise>
        </ray>
        <plugin name='gazebo_ros_laser' filename='libgazebo_ros_gpu_laser.so'>
          <frameName>laser</frameName>
          <topicName>sensors/laser</topicName>
        </plugin>
      </sensor> -->
    </link>
    <joint name='left_rocker_joint' type='revolute'>
      <pose relative_to='base_link'>0.071 0.155 0.0118 0 0 0</pose>
      <parent>base_link</parent>
      <child>left_rocker_link</child>
      <axis>
        <xyz>0 1 0</xyz>
        <limit>
          <!-- <lower>-1e+16</lower>
          <upper>1e+16</upper> -->
          <lower>0</lower>
          <upper>0</upper>
        </limit>
        <dynamics>
          <spring_reference>0</spring_reference>
          <spring_stiffness>0</spring_stiffness>
          <damping>0.1</damping>
          <friction>0.1</friction>
        </dynamics>
      </axis>
      <physics>
        <provide_feedback>1</provide_feedback>
        <ode>
          <implicit_spring_damper>1</implicit_spring_damper>
          <cfm_damping>1</cfm_damping>
          <limit>
            <cfm>0</cfm>
            <erp>0.2</erp>
          </limit>
        </ode>
      </physics>
    </joint>
    <link name='left_rocker_link'>
      <pose relative_to='left_rocker_joint'>0 0 0 0 0 0</pose>
      <inertial>
        <pose>0 0 0 0 0 0</pose>
        <mass>0.25</mass>
        <inertia>
          <ixx>9.375e-06</ixx>
          <ixy>0</ixy>
          <ixz>0</ixz>
          <iyy>0.000213021</iyy>
          <iyz>0</iyz>
          <izz>0.000213021</izz>
        </inertia>
      </inertial>
      <collision name='left_rocker_link_collision'>
        <pose>0 0 0 0 0 0</pose>
        <geometry>
          <box>
            <size>0.1 0.015 0.015</size>
          </box>
        </geometry>
        <surface>
          <contact>
            <ode/>
          </contact>
          <friction>
            <ode/>
          </friction>
        </surface>
      </collision>
      <visual name='left_rocker_link_visual'>
        <pose>0 0 0 0 0 0</pose>
        <geometry>
          <mesh>
            <scale>1 1 1</scale>
            <uri>model://sawppy/meshes/bases/left_rocker_asm.stl</uri>
          </mesh>
        </geometry>
        <material>
          <ambient>0.175 0.175 0.175 1</ambient>
          <diffuse>0.175 0.175 0.175 1</diffuse>
          <specular>0.175 0.175 0.175 1</specular>
        </material>
      </visual>
      <gravity>1</gravity>
      <velocity_decay/>
    </link>
    <joint name='front_left_steer_joint' type='revolute'>
      <pose relative_to='left_rocker_link'>0.2116 0.075 -0.0279 0 0 0</pose>
      <parent>left_rocker_link</parent>
      <child>front_left_steer_link</child>
      <axis>
        <xyz>0 0 1</xyz>
        <limit>
          <lower>-1e+16</lower>
          <upper>1e+16</upper>
        </limit>
        <dynamics>
          <spring_reference>0</spring_reference>
          <spring_stiffness>0</spring_stiffness>
          <damping>0.1</damping>
          <friction>0.1</friction>
        </dynamics>
      </axis>
      <physics>
        <provide_feedback>1</provide_feedback>
        <ode>
          <limit>
            <cfm>0</cfm>
            <erp>0.2</erp>
          </limit>
        </ode>
      </physics>
    </joint>
    <link name='front_left_steer_link'>
      <pose relative_to='front_left_steer_joint'>0 0 0 0 0 0</pose>
      <inertial>
        <pose>0 0 0 0 0 0</pose>
        <mass>0.25</mass>
        <inertia>
          <ixx>0.000416667</ixx>
          <ixy>0</ixy>
          <ixz>0</ixz>
          <iyy>0.000416667</iyy>
          <iyz>0</iyz>
          <izz>0.000416667</izz>
        </inertia>
      </inertial>
      <collision name='front_left_steer_link_collision'>
        <pose>0 0 0 0 0 0</pose>
        <geometry>
          <box>
            <size>0.1 0.1 0.1</size>
          </box>
        </geometry>
        <surface>
          <contact>
            <ode/>
          </contact>
          <friction>
            <ode/>
          </friction>
        </surface>
      </collision>
      <visual name='front_left_steer_link_visual'>
        <pose>0 0 0 0 0 0</pose>
        <geometry>
          <mesh>
            <scale>1 1 1</scale>
            <uri>model://sawppy/meshes/bases/front_left_steering_asm.stl</uri>
          </mesh>
        </geometry>
        <material>
          <ambient>0.175 0.175 0.175 1</ambient>
          <diffuse>0.175 0.175 0.175 1</diffuse>
          <specular>0.175 0.175 0.175 1</specular>
        </material>
      </visual>
      <gravity>1</gravity>
      <velocity_decay/>
    </link>
    <joint name='front_left_wheel_joint' type='revolute'>
      <pose relative_to='front_left_steer_link'>0 0 -0.132 0 0 0</pose>
      <parent>front_left_steer_link</parent>
      <child>front_left_wheel_link</child>
      <axis>
        <xyz>0 1 0</xyz>
        <limit>
          <lower>-1e+16</lower>
          <upper>1e+16</upper>
        </limit>
        <dynamics>
          <spring_reference>0</spring_reference>
          <spring_stiffness>0</spring_stiffness>
          <damping>0.01</damping>
          <friction>0.01</friction>
        </dynamics>
      </axis>
      <physics>
        <provide_feedback>1</provide_feedback>
        <ode>
          <limit>
            <cfm>0</cfm>
            <erp>0.2</erp>
          </limit>
        </ode>
      </physics>
    </joint>
    <link name='front_left_wheel_link'>
      <pose relative_to='front_left_wheel_joint'>0 0 0 0 0 0</pose>
      <inertial>
        <pose>0 0 0 0 0 0</pose>
        <mass>0.25</mass>
        <inertia>
          <ixx>0.000433333</ixx>
          <ixy>0</ixy>
          <ixz>0</ixz>
          <iyy>0.000433333</iyy>
          <iyz>0</iyz>
          <izz>0.00045</izz>
        </inertia>
      </inertial>
      <collision name='front_left_wheel_link_collision'>
        <pose degrees="true">0 0 0 90 0 0</pose>
        <geometry>
          <cylinder>
            <length>0.1</length>
            <radius>0.06</radius>
          </cylinder>
        </geometry>
        <surface>
          <contact>
            <ode/>
          </contact>
          <friction>
            <ode/>
          </friction>
        </surface>
      </collision>
      <visual name='front_left_wheel_link_visual'>
        <pose degrees="true">0 0 0 90 0 0</pose>
        <geometry>
          <mesh>
            <scale>1 1 1</scale>
            <uri>model://sawppy/meshes/wheels/wheel_asm.stl</uri>
          </mesh>
        </geometry>
        <material>
          <ambient>0.001 0.005 0.2 1</ambient>
          <diffuse>0.001 0.005 0.2 1</diffuse>
          <specular>0.01 0.01 0.01 1</specular>
        </material>
      </visual>
      <gravity>1</gravity>
      <velocity_decay/>
    </link>
    <joint name='left_bogie_joint' type='revolute'>
      <pose relative_to='left_rocker_link'>-0.181 0.025 -0.062 0 0 0</pose>
      <parent>left_rocker_link</parent>
      <child>left_bogie_link</child>
      <axis>
        <xyz>0 1 0</xyz>
        <limit>
          <lower>-0.785398</lower>
          <upper>0.785398</upper>
          <effort>100</effort>
          <velocity>100</velocity>
        </limit>
        <dynamics>
          <spring_reference>0</spring_reference>
          <spring_stiffness>0</spring_stiffness>
          <damping>0.1</damping>
          <friction>0.1</friction>
        </dynamics>
      </axis>
      <physics>
        <provide_feedback>1</provide_feedback>
        <ode>
          <implicit_spring_damper>1</implicit_spring_damper>
          <cfm_damping>1</cfm_damping>
          <limit>
            <cfm>0</cfm>
            <erp>0.2</erp>
          </limit>
        </ode>
      </physics>
    </joint>
    <link name='left_bogie_link'>
      <pose relative_to='left_bogie_joint'>0 0 0 0 0 0</pose>
      <inertial>
        <pose>0 0 0 0 0 0</pose>
        <mass>0.25</mass>
        <inertia>
          <ixx>9.375e-06</ixx>
          <ixy>0</ixy>
          <ixz>0</ixz>
          <iyy>0.000213021</iyy>
          <iyz>0</iyz>
          <izz>0.000213021</izz>
        </inertia>
      </inertial>
      <collision name='left_bogie_link_collision'>
        <pose>0 0 0 0 0 0</pose>
        <geometry>
          <box>
            <size>0.1 0.015 0.015</size>
          </box>
        </geometry>
        <surface>
          <contact>
            <ode/>
          </contact>
          <friction>
            <ode/>
          </friction>
        </surface>
      </collision>
      <visual name='left_bogie_link_visual'>
        <pose>0 0 0 0 0 0</pose>
        <geometry>
          <mesh>
            <scale>1 1 1</scale>
            <uri>model://sawppy/meshes/bases/left_bogie_asm.stl</uri>
          </mesh>
        </geometry>
        <material>
          <ambient>0.175 0.175 0.175 1</ambient>
          <diffuse>0.175 0.175 0.175 1</diffuse>
          <specular>0.175 0.175 0.175 1</specular>
        </material>
      </visual>
      <gravity>1</gravity>
      <velocity_decay/>
    </link>
    <joint name='back_left_steer_joint' type='revolute'>
      <pose relative_to='left_bogie_link'>-0.149 0.05 0.0338 0 0 0</pose>
      <parent>left_bogie_link</parent>
      <child>back_left_steer_link</child>
      <axis>
        <xyz>0 0 1</xyz>
        <limit>
          <lower>-1e+16</lower>
          <upper>1e+16</upper>
        </limit>
        <dynamics>
          <spring_reference>0</spring_reference>
          <spring_stiffness>0</spring_stiffness>
          <damping>0.1</damping>
          <friction>0.1</friction>
        </dynamics>
      </axis>
      <physics>
        <provide_feedback>1</provide_feedback>
        <ode>
          <limit>
            <cfm>0</cfm>
            <erp>0.2</erp>
          </limit>
        </ode>
      </physics>
    </joint>
    <link name='back_left_steer_link'>
      <pose relative_to='back_left_steer_joint'>0 0 0 0 0 0</pose>
      <inertial>
        <pose>0 0 0 0 0 0</pose>
        <mass>0.25</mass>
        <inertia>
          <ixx>0.000416667</ixx>
          <ixy>0</ixy>
          <ixz>0</ixz>
          <iyy>0.000416667</iyy>
          <iyz>0</iyz>
          <izz>0.000416667</izz>
        </inertia>
      </inertial>
      <collision name='back_left_steer_link_collision'>
        <pose>0 0 0 0 0 0</pose>
        <geometry>
          <box>
            <size>0.1 0.1 0.1</size>
          </box>
        </geometry>
        <surface>
          <contact>
            <ode/>
          </contact>
          <friction>
            <ode/>
          </friction>
        </surface>
      </collision>
      <visual name='back_left_steer_link_visual'>
        <pose>0 0 0 0 0 0</pose>
        <geometry>
          <mesh>
            <scale>1 1 1</scale>
            <uri>model://sawppy/meshes/bases/back_left_steering_asm.stl</uri>
          </mesh>
        </geometry>
        <material>
          <ambient>0.175 0.175 0.175 1</ambient>
          <diffuse>0.175 0.175 0.175 1</diffuse>
          <specular>0.175 0.175 0.175 1</specular>
        </material>
      </visual>
      <gravity>1</gravity>
      <velocity_decay/>
    </link>
    <joint name='back_left_wheel_joint' type='revolute'>
      <pose relative_to='back_left_steer_link'>0 0 -0.132 0 0 0</pose>
      <parent>back_left_steer_link</parent>
      <child>back_left_wheel_link</child>
      <axis>
        <xyz>0 1 0</xyz>
        <limit>
          <lower>-1e+16</lower>
          <upper>1e+16</upper>
        </limit>
        <dynamics>
          <spring_reference>0</spring_reference>
          <spring_stiffness>0</spring_stiffness>
          <damping>0.01</damping>
          <friction>0.01</friction>
        </dynamics>
      </axis>
      <physics>
        <provide_feedback>1</provide_feedback>
        <ode>
          <limit>
            <cfm>0</cfm>
            <erp>0.2</erp>
          </limit>
        </ode>
      </physics>
    </joint>
    <link name='back_left_wheel_link'>
      <pose relative_to='back_left_wheel_joint'>0 0 0 0 0 0</pose>
      <inertial>
        <pose>0 0 0 0 0 0</pose>
        <mass>0.25</mass>
        <inertia>
          <ixx>0.000433333</ixx>
          <ixy>0</ixy>
          <ixz>0</ixz>
          <iyy>0.000433333</iyy>
          <iyz>0</iyz>
          <izz>0.00045</izz>
        </inertia>
      </inertial>
      <collision name='back_left_wheel_link_collision'>
        <pose degrees="true">0 0 0 90 0 0</pose>
        <geometry>
          <cylinder>
            <length>0.1</length>
            <radius>0.06</radius>
          </cylinder>
        </geometry>
        <surface>
          <contact>
            <ode/>
          </contact>
          <friction>
            <ode/>
          </friction>
        </surface>
      </collision>
      <visual name='back_left_wheel_link_visual'>
        <pose degrees="true">0 0 0 90 0 0</pose>
        <geometry>
          <mesh>
            <scale>1 1 1</scale>
            <uri>model://sawppy/meshes/wheels/wheel_asm.stl</uri>
          </mesh>
        </geometry>
        <material>
          <ambient>0.001 0.005 0.2 1</ambient>
          <diffuse>0.001 0.005 0.2 1</diffuse>
          <specular>0.01 0.01 0.01 1</specular>
        </material>
      </visual>
      <gravity>1</gravity>
      <velocity_decay/>
    </link>
    <joint name='mid_left_wheel_joint' type='revolute'>
      <pose relative_to='left_bogie_link'>0.1063 0.0929 -0.0959 0 0 0</pose>
      <parent>left_bogie_link</parent>
      <child>mid_left_wheel_link</child>
      <axis>
        <xyz>0 1 0</xyz>
        <limit>
          <lower>-1e+16</lower>
          <upper>1e+16</upper>
        </limit>
        <dynamics>
          <spring_reference>0</spring_reference>
          <spring_stiffness>0</spring_stiffness>
          <damping>0.01</damping>
          <friction>0.01</friction>
        </dynamics>
      </axis>
      <physics>
        <provide_feedback>1</provide_feedback>
        <ode>
          <limit>
            <cfm>0</cfm>
            <erp>0.2</erp>
          </limit>
        </ode>
      </physics>
    </joint>
    <link name='mid_left_wheel_link'>
      <pose relative_to='mid_left_wheel_joint'>0 0 0 0 0 0</pose>
      <inertial>
        <pose>0 0 0 0 0 0</pose>
        <mass>0.25</mass>
        <inertia>
          <ixx>0.000433333</ixx>
          <ixy>0</ixy>
          <ixz>0</ixz>
          <iyy>0.000433333</iyy>
          <iyz>0</iyz>
          <izz>0.00045</izz>
        </inertia>
      </inertial>
      <collision name='mid_left_wheel_link_collision'>
        <pose degrees="true">0 0 0 90 0 0</pose>
        <geometry>
          <cylinder>
            <length>0.1</length>
            <radius>0.06</radius>
          </cylinder>
        </geometry>
        <surface>
          <contact>
            <ode/>
          </contact>
          <friction>
            <ode/>
          </friction>
        </surface>
      </collision>
      <visual name='mid_left_wheel_link_visual'>
        <pose degrees="true">0 0 0 90 0 0</pose>
        <geometry>
          <mesh>
            <scale>1 1 1</scale>
            <uri>model://sawppy/meshes/wheels/wheel_asm.stl</uri>
          </mesh>
        </geometry>
        <material>
          <ambient>0.001 0.005 0.2 1</ambient>
          <diffuse>0.001 0.005 0.2 1</diffuse>
          <specular>0.01 0.01 0.01 1</specular>
        </material>
      </visual>
      <gravity>1</gravity>
      <velocity_decay/>
    </link>
    <joint name='right_rocker_joint' type='revolute'>
      <pose relative_to='base_link'>0.071 -0.155 0.0118 0 0 0</pose>
      <parent>base_link</parent>
      <child>right_rocker_link</child>
      <axis>
        <xyz>0 1 0</xyz>
        <limit>
          <!-- <lower>-1e+16</lower>
          <upper>1e+16</upper> -->
          <lower>0</lower>
          <upper>0</upper>
        </limit>
        <dynamics>
          <spring_reference>0</spring_reference>
          <spring_stiffness>0</spring_stiffness>
          <damping>0.1</damping>
          <friction>0.1</friction>
        </dynamics>
      </axis>
      <physics>
        <provide_feedback>1</provide_feedback>
        <ode>
          <implicit_spring_damper>1</implicit_spring_damper>
          <cfm_damping>1</cfm_damping>
          <limit>
            <cfm>0</cfm>
            <erp>0.2</erp>
          </limit>
        </ode>
      </physics>
    </joint>
    <link name='right_rocker_link'>
      <pose relative_to='right_rocker_joint'>0 0 0 0 0 0</pose>
      <inertial>
        <pose>0 0 0 0 0 0</pose>
        <mass>0.25</mass>
        <inertia>
          <ixx>9.375e-06</ixx>
          <ixy>0</ixy>
          <ixz>0</ixz>
          <iyy>0.000213021</iyy>
          <iyz>0</iyz>
          <izz>0.000213021</izz>
        </inertia>
      </inertial>
      <collision name='right_rocker_link_collision'>
        <pose>0 0 0 0 0 0</pose>
        <geometry>
          <box>
            <size>0.1 0.015 0.015</size>
          </box>
        </geometry>
        <surface>
          <contact>
            <ode/>
          </contact>
          <friction>
            <ode/>
          </friction>
        </surface>
      </collision>
      <visual name='right_rocker_link_visual'>
        <pose>0 0 0 0 0 0</pose>
        <geometry>
          <mesh>
            <scale>1 1 1</scale>
            <uri>model://sawppy/meshes/bases/right_rocker_asm.stl</uri>
          </mesh>
        </geometry>
        <material>
          <ambient>0.175 0.175 0.175 1</ambient>
          <diffuse>0.175 0.175 0.175 1</diffuse>
          <specular>0.175 0.175 0.175 1</specular>
        </material>
      </visual>
      <gravity>1</gravity>
      <velocity_decay/>
    </link>
    <joint name='front_right_steer_joint' type='revolute'>
      <pose relative_to='right_rocker_link'>0.2116 -0.075 -0.0279 0 0 0</pose>
      <parent>right_rocker_link</parent>
      <child>front_right_steer_link</child>
      <axis>
        <xyz>0 0 1</xyz>
        <limit>
          <lower>-1e+16</lower>
          <upper>1e+16</upper>
        </limit>
        <dynamics>
          <spring_reference>0</spring_reference>
          <spring_stiffness>0</spring_stiffness>
          <damping>0.1</damping>
          <friction>0.1</friction>
        </dynamics>
      </axis>
      <physics>
        <provide_feedback>1</provide_feedback>
        <ode>
          <limit>
            <cfm>0</cfm>
            <erp>0.2</erp>
          </limit>
        </ode>
      </physics>
    </joint>
    <link name='front_right_steer_link'>
      <pose relative_to='front_right_steer_joint'>0 0 0 0 0 0</pose>
      <inertial>
        <pose>0 0 0 0 0 0</pose>
        <mass>0.25</mass>
        <inertia>
          <ixx>0.000416667</ixx>
          <ixy>0</ixy>
          <ixz>0</ixz>
          <iyy>0.000416667</iyy>
          <iyz>0</iyz>
          <izz>0.000416667</izz>
        </inertia>
      </inertial>
      <collision name='front_right_steer_link_collision'>
        <pose>0 0 0 0 0 0</pose>
        <geometry>
          <box>
            <size>0.1 0.1 0.1</size>
          </box>
        </geometry>
        <surface>
          <contact>
            <ode/>
          </contact>
          <friction>
            <ode/>
          </friction>
        </surface>
      </collision>
      <visual name='front_right_steer_link_visual'>
        <pose>0 0 0 0 0 0</pose>
        <geometry>
          <mesh>
            <scale>1 1 1</scale>
            <uri>model://sawppy/meshes/bases/front_right_steering_asm.stl</uri>
          </mesh>
        </geometry>
        <material>
          <ambient>0.175 0.175 0.175 1</ambient>
          <diffuse>0.175 0.175 0.175 1</diffuse>
          <specular>0.175 0.175 0.175 1</specular>
        </material>
      </visual>
      <gravity>1</gravity>
      <velocity_decay/>
    </link>
    <joint name='front_right_wheel_joint' type='revolute'>
      <pose relative_to='front_right_steer_link'>0 0 -0.132 0 0 0</pose>
      <parent>front_right_steer_link</parent>
      <child>front_right_wheel_link</child>
      <axis>
        <xyz>0 1 0</xyz>
        <limit>
          <lower>-1e+16</lower>
          <upper>1e+16</upper>
        </limit>
        <dynamics>
          <spring_reference>0</spring_reference>
          <spring_stiffness>0</spring_stiffness>
          <damping>0.01</damping>
          <friction>0.01</friction>
        </dynamics>
      </axis>
      <physics>
        <provide_feedback>1</provide_feedback>
        <ode>
          <limit>
            <cfm>0</cfm>
            <erp>0.2</erp>
          </limit>
        </ode>
      </physics>
    </joint>
    <link name='front_right_wheel_link'>
      <pose relative_to='front_right_wheel_joint'>0 0 0 0 0 0</pose>
      <inertial>
        <pose>0 0 0 0 0 0</pose>
        <mass>0.25</mass>
        <inertia>
          <ixx>0.000433333</ixx>
          <ixy>0</ixy>
          <ixz>0</ixz>
          <iyy>0.000433333</iyy>
          <iyz>0</iyz>
          <izz>0.00045</izz>
        </inertia>
      </inertial>
      <collision name='front_right_wheel_link_collision'>
        <pose degrees="true">0 0 0 -90 0 0</pose>
        <geometry>
          <cylinder>
            <length>0.1</length>
            <radius>0.06</radius>
          </cylinder>
        </geometry>
        <surface>
          <contact>
            <ode/>
          </contact>
          <friction>
            <ode/>
          </friction>
        </surface>
      </collision>
      <visual name='front_right_wheel_link_visual'>
        <pose degrees="true">0 0 0 -90 0 0</pose>
        <geometry>
          <mesh>
            <scale>1 1 1</scale>
            <uri>model://sawppy/meshes/wheels/wheel_asm.stl</uri>
          </mesh>
        </geometry>
        <material>
          <ambient>0.001 0.005 0.2 1</ambient>
          <diffuse>0.001 0.005 0.2 1</diffuse>
          <specular>0.01 0.01 0.01 1</specular>
        </material>
      </visual>
      <gravity>1</gravity>
      <velocity_decay/>
    </link>
    <joint name='right_bogie_joint' type='revolute'>
      <pose relative_to='right_rocker_link'>-0.181 -0.025 -0.062 0 0 0</pose>
      <parent>right_rocker_link</parent>
      <child>right_bogie_link</child>
      <axis>
        <xyz>0 1 0</xyz>
        <limit>
          <lower>-0.785398</lower>
          <upper>0.785398</upper>
          <effort>100</effort>
          <velocity>100</velocity>
        </limit>
        <dynamics>
          <spring_reference>0</spring_reference>
          <spring_stiffness>0</spring_stiffness>
          <damping>0.1</damping>
          <friction>0.1</friction>
        </dynamics>
      </axis>
      <physics>
        <provide_feedback>1</provide_feedback>
        <ode>
          <implicit_spring_damper>1</implicit_spring_damper>
          <cfm_damping>1</cfm_damping>
          <limit>
            <cfm>0</cfm>
            <erp>0.2</erp>
          </limit>
        </ode>
      </physics>
    </joint>
    <link name='right_bogie_link'>
      <pose relative_to='right_bogie_joint'>0 0 0 0 0 0</pose>
      <inertial>
        <pose>0 0 0 0 0 0</pose>
        <mass>0.25</mass>
        <inertia>
          <ixx>9.375e-06</ixx>
          <ixy>0</ixy>
          <ixz>0</ixz>
          <iyy>0.000213021</iyy>
          <iyz>0</iyz>
          <izz>0.000213021</izz>
        </inertia>
      </inertial>
      <collision name='right_bogie_link_collision'>
        <pose>0 0 0 0 0 0</pose>
        <geometry>
          <box>
            <size>0.1 0.015 0.015</size>
          </box>
        </geometry>
        <surface>
          <contact>
            <ode/>
          </contact>
          <friction>
            <ode/>
          </friction>
        </surface>
      </collision>
      <visual name='right_bogie_link_visual'>
        <pose>0 0 0 0 0 0</pose>
        <geometry>
          <mesh>
            <scale>1 1 1</scale>
            <uri>model://sawppy/meshes/bases/right_bogie_asm.stl</uri>
          </mesh>
        </geometry>
        <material>
          <ambient>0.175 0.175 0.175 1</ambient>
          <diffuse>0.175 0.175 0.175 1</diffuse>
          <specular>0.175 0.175 0.175 1</specular>
        </material>
      </visual>
      <gravity>1</gravity>
      <velocity_decay/>
    </link>
    <joint name='back_right_steer_joint' type='revolute'>
      <pose relative_to='right_bogie_link'>-0.149 -0.05 0.0338 0 0 0</pose>
      <parent>right_bogie_link</parent>
      <child>back_right_steer_link</child>
      <axis>
        <xyz>0 0 1</xyz>
        <limit>
          <lower>-1e+16</lower>
          <upper>1e+16</upper>
        </limit>
        <dynamics>
          <spring_reference>0</spring_reference>
          <spring_stiffness>0</spring_stiffness>
          <damping>0.1</damping>
          <friction>0.1</friction>
        </dynamics>
      </axis>
      <physics>
        <provide_feedback>1</provide_feedback>
        <ode>
          <limit>
            <cfm>0</cfm>
            <erp>0.2</erp>
          </limit>
        </ode>
      </physics>
    </joint>
    <link name='back_right_steer_link'>
      <pose relative_to='back_right_steer_joint'>0 0 0 0 0 0</pose>
      <inertial>
        <pose>0 0 0 0 0 0</pose>
        <mass>0.25</mass>
        <inertia>
          <ixx>0.000416667</ixx>
          <ixy>0</ixy>
          <ixz>0</ixz>
          <iyy>0.000416667</iyy>
          <iyz>0</iyz>
          <izz>0.000416667</izz>
        </inertia>
      </inertial>
      <collision name='back_right_steer_link_collision'>
        <pose>0 0 0 0 0 0</pose>
        <geometry>
          <box>
            <size>0.1 0.1 0.1</size>
          </box>
        </geometry>
        <surface>
          <contact>
            <ode/>
          </contact>
          <friction>
            <ode/>
          </friction>
        </surface>
      </collision>
      <visual name='back_right_steer_link_visual'>
        <pose>0 0 0 0 0 0</pose>
        <geometry>
          <mesh>
            <scale>1 1 1</scale>
            <uri>model://sawppy/meshes/bases/back_right_steering_asm.stl</uri>
          </mesh>
        </geometry>
        <material>
          <ambient>0.175 0.175 0.175 1</ambient>
          <diffuse>0.175 0.175 0.175 1</diffuse>
          <specular>0.175 0.175 0.175 1</specular>
        </material>
      </visual>
      <gravity>1</gravity>
      <velocity_decay/>
    </link>
    <joint name='back_right_wheel_joint' type='revolute'>
      <pose relative_to='back_right_steer_link'>0 0 -0.132 0 0 0</pose>
      <parent>back_right_steer_link</parent>
      <child>back_right_wheel_link</child>
      <axis>
        <xyz>0 1 0</xyz>
        <limit>
          <lower>-1e+16</lower>
          <upper>1e+16</upper>
        </limit>
        <dynamics>
          <spring_reference>0</spring_reference>
          <spring_stiffness>0</spring_stiffness>
          <damping>0.01</damping>
          <friction>0.01</friction>
        </dynamics>
      </axis>
      <physics>
        <provide_feedback>1</provide_feedback>
        <ode>
          <limit>
            <cfm>0</cfm>
            <erp>0.2</erp>
          </limit>
        </ode>
      </physics>
    </joint>
    <link name='back_right_wheel_link'>
      <pose relative_to='back_right_wheel_joint'>0 0 0 0 0 0</pose>
      <inertial>
        <pose>0 0 0 0 0 0</pose>
        <mass>0.25</mass>
        <inertia>
          <ixx>0.000433333</ixx>
          <ixy>0</ixy>
          <ixz>0</ixz>
          <iyy>0.000433333</iyy>
          <iyz>0</iyz>
          <izz>0.00045</izz>
        </inertia>
      </inertial>
      <collision name='back_right_wheel_link_collision'>
        <pose degrees="true">0 0 0 -90 0 0</pose>
        <geometry>
          <cylinder>
            <length>0.1</length>
            <radius>0.06</radius>
          </cylinder>
        </geometry>
        <surface>
          <contact>
            <ode/>
          </contact>
          <friction>
            <ode/>
          </friction>
        </surface>
      </collision>
      <visual name='back_right_wheel_link_visual'>
        <pose degrees="true">0 0 0 -90 0 0</pose>
        <geometry>
          <mesh>
            <scale>1 1 1</scale>
            <uri>model://sawppy/meshes/wheels/wheel_asm.stl</uri>
          </mesh>
        </geometry>
        <material>
          <ambient>0.001 0.005 0.2 1</ambient>
          <diffuse>0.001 0.005 0.2 1</diffuse>
          <specular>0.01 0.01 0.01 1</specular>
        </material>
      </visual>
      <gravity>1</gravity>
      <velocity_decay/>
    </link>
    <joint name='mid_right_wheel_joint' type='revolute'>
      <pose relative_to='right_bogie_link'>0.1063 -0.0929 -0.0959 0 0 0</pose>
      <parent>right_bogie_link</parent>
      <child>mid_right_wheel_link</child>
      <axis>
        <xyz>0 1 0</xyz>
        <limit>
          <lower>-1e+16</lower>
          <upper>1e+16</upper>
        </limit>
        <dynamics>
          <spring_reference>0</spring_reference>
          <spring_stiffness>0</spring_stiffness>
          <damping>0.01</damping>
          <friction>0.01</friction>
        </dynamics>
      </axis>
      <physics>
        <provide_feedback>1</provide_feedback>
        <ode>
          <limit>
            <cfm>0</cfm>
            <erp>0.2</erp>
          </limit>
        </ode>
      </physics>
    </joint>
    <link name='mid_right_wheel_link'>
      <pose relative_to='mid_right_wheel_joint'>0 0 0 0 0 0</pose>
      <inertial>
        <pose>0 0 0 0 0 0</pose>
        <mass>0.25</mass>
        <inertia>
          <ixx>0.000433333</ixx>
          <ixy>0</ixy>
          <ixz>0</ixz>
          <iyy>0.000433333</iyy>
          <iyz>0</iyz>
          <izz>0.00045</izz>
        </inertia>
      </inertial>
      <collision name='mid_right_wheel_link_collision'>
        <pose degrees="true">0 0 0 -90 0 0</pose>
        <geometry>
          <cylinder>
            <length>0.1</length>
            <radius>0.06</radius>
          </cylinder>
        </geometry>
        <surface>
          <contact>
            <ode/>
          </contact>
          <friction>
            <ode/>
          </friction>
        </surface>
      </collision>
      <visual name='mid_right_wheel_link_visual'>
        <pose degrees="true">0 0 0 -90 0 0</pose>
        <geometry>
          <mesh>
            <scale>1 1 1</scale>
            <uri>model://sawppy/meshes/wheels/wheel_asm.stl</uri>
          </mesh>
        </geometry>
        <material>
          <ambient>0.001 0.005 0.2 1</ambient>
          <diffuse>0.001 0.005 0.2 1</diffuse>
          <specular>0.01 0.01 0.01 1</specular>
        </material>
      </visual>
      <gravity>1</gravity>
      <velocity_decay/>
    </link>
    <link name='left_turnbuckle_link'>
      <pose>0.035 0.17 0.07 0 0 0</pose>
      <visual name='left_turnbuckle_visual'>
        <pose degrees="true">0 0 0 90 0 0</pose>
        <geometry>
          <mesh>
            <uri>model://sawppy/meshes/bases/turnbuckle.stl</uri>
          </mesh>
        </geometry>
        <material>
          <ambient>0.001 0.005 0.2 1</ambient>
          <diffuse>0.001 0.005 0.2 1</diffuse>
          <specular>0.01 0.01 0.01 1</specular>
        </material>
      </visual>
      <collision name='left_turnbuckle_collision'>
        <pose degrees="true">0 0 0 0 90 0</pose>
        <geometry>
          <cylinder>
            <length>0.07</length>
            <radius>0.0025</radius>
          </cylinder>
        </geometry>
      </collision>
      <inertial>
        <mass>0.01</mass>
        <inertia>
          <ixx>0.0001</ixx>
          <ixy>0</ixy>
          <ixz>0</ixz>
          <iyy>0.0001</iyy>
          <iyz>0</iyz>
          <izz>0.0001</izz>
        </inertia>
      </inertial>
    </link>
    <!-- <joint name='back_left_turnbuckle_joint' type='ball'>
      <pose>-0.035 0 0 0 0 0</pose>
      <parent>diff_brace_link</parent>
      <child>left_turnbuckle_link</child>
    </joint> -->
    <!-- <joint name='front_left_turnbuckle_joint' type='ball'> -->
    <joint name='front_left_turnbuckle_joint' type='fixed'>
      <pose>0.035 0 0 0 0 0</pose>
      <parent>left_rocker_link</parent>
      <child>left_turnbuckle_link</child>
    </joint>
    <link name='right_turnbuckle_link'>
      <pose>0.035 -0.17 0.07 0 0 0</pose>
      <visual name='right_turnbuckle_visual'>
        <pose degrees="true">0 0 0 90 0 0</pose>
        <geometry>
          <mesh>
            <uri>model://sawppy/meshes/bases/turnbuckle.stl</uri>
          </mesh>
        </geometry>
        <material>
          <ambient>0.001 0.005 0.2 1</ambient>
          <diffuse>0.001 0.005 0.2 1</diffuse>
          <specular>0.01 0.01 0.01 1</specular>
        </material>
      </visual>
      <collision name='right_turnbuckle_collision'>
        <pose degrees="true">0 0 0 0 90 0</pose>
        <geometry>
          <cylinder>
            <length>0.07</length>
            <radius>0.0025</radius>
          </cylinder>
        </geometry>
      </collision>
      <inertial>
        <mass>0.01</mass>
        <inertia>
          <ixx>0.0001</ixx>
          <ixy>0</ixy>
          <ixz>0</ixz>
          <iyy>0.0001</iyy>
          <iyz>0</iyz>
          <izz>0.0001</izz>
        </inertia>
      </inertial>
    </link>
    <!-- <joint name='back_right_turnbuckle_joint' type='ball'>
      <pose>-0.035 0 0 0 0 0</pose>
      <parent>diff_brace_link</parent>
      <child>right_turnbuckle_link</child>
    </joint> -->
    <!-- <joint name='front_right_turnbuckle_joint' type='ball'> -->
    <joint name='front_right_turnbuckle_joint' type='fixed'>
      <pose>0.035 0 0 0 0 0</pose>
      <parent>right_rocker_link</parent>
      <child>right_turnbuckle_link</child>
    </joint>

    <!-- sensors -->
    <link name='imu_link'>
      <inertial>
        <pose>0 0 0 0 0 0</pose>
        <mass>0.15</mass>
        <inertia>
          <ixx>0.00002</ixx>
          <ixy>0</ixy>
          <ixz>0</ixz>
          <iyy>0.00002</iyy>
          <iyz>0</iyz>
          <izz>0.00002</izz>
        </inertia>
      </inertial>
      <sensor name="imu_sensor" type="imu">
        <pose degrees="true">0 0 0 180 0 0</pose>
        <always_on>1</always_on>
        <update_rate>1000.0</update_rate>
      </sensor>
    </link>
    <joint name='imu_joint' type='revolute'>
      <child>imu_link</child>
      <parent>base_link</parent>
      <axis>
        <xyz>0 0 1</xyz>
        <limit>
          <lower>0</lower>
          <upper>0</upper>
          <effort>0</effort>
          <velocity>0</velocity>
        </limit>
        <dynamics>
          <damping>1.0</damping>
        </dynamics>
      </axis>
    </joint>

    <!-- plugins -->
    <plugin filename="gz-sim-joint-state-publisher-system"
      name="gz::sim::systems::JointStatePublisher">
    </plugin>
    <plugin filename="gz-sim-apply-joint-force-system"
      name="gz::sim::systems::ApplyJointForce">
      <joint_name>front_left_wheel_joint</joint_name>
    </plugin>
    <plugin filename="gz-sim-apply-joint-force-system"
      name="gz::sim::systems::ApplyJointForce">
      <joint_name>front_right_wheel_joint</joint_name>
    </plugin>
    <plugin filename="gz-sim-apply-joint-force-system"
      name="gz::sim::systems::ApplyJointForce">
      <joint_name>mid_left_wheel_joint</joint_name>
    </plugin>
    <plugin filename="gz-sim-apply-joint-force-system"
      name="gz::sim::systems::ApplyJointForce">
      <joint_name>mid_right_wheel_joint</joint_name>
    </plugin>
    <plugin filename="gz-sim-apply-joint-force-system"
      name="gz::sim::systems::ApplyJointForce">
      <joint_name>back_left_wheel_joint</joint_name>
    </plugin>
    <plugin filename="gz-sim-apply-joint-force-system"
      name="gz::sim::systems::ApplyJointForce">
      <joint_name>back_right_wheel_joint</joint_name>
    </plugin>
    <plugin filename="gz-sim-apply-joint-force-system"
      name="gz::sim::systems::ApplyJointForce">
      <joint_name>front_left_steer_joint</joint_name>
    </plugin>
    <plugin filename="gz-sim-apply-joint-force-system"
      name="gz::sim::systems::ApplyJointForce">
      <joint_name>front_right_steer_joint</joint_name>
    </plugin>
    <plugin filename="gz-sim-apply-joint-force-system"
      name="gz::sim::systems::ApplyJointForce">
      <joint_name>back_left_steer_joint</joint_name>
    </plugin>
    <plugin filename="gz-sim-apply-joint-force-system"
      name="gz::sim::systems::ApplyJointForce">
      <joint_name>back_right_steer_joint</joint_name>
    </plugin>


    <plugin name="ArduPilotPlugin" filename="ArduPilotPlugin">
      <!-- Port settings -->
      <fdm_addr>127.0.0.1</fdm_addr>
      <fdm_port_in>9002</fdm_port_in>
      <connectionTimeoutMaxCount>5</connectionTimeoutMaxCount>
      <lock_step>1</lock_step>

      <modelXYZToAirplaneXForwardZDown degrees="true">0 0 0 180 0 0</modelXYZToAirplaneXForwardZDown>
      <gazeboXYZToNED degrees="true">0 0 0 180 0 90</gazeboXYZToNED>

      <!-- Sensors -->
      <imuName>imu_sensor</imuName>

      <!-- Wheel servos -->

      <!--
        SERVO1_FUNCTION 94 (Script 1)
        SERVO1_MIN 1000
        SERVO1_MAX 2000
      -->
      <control channel="0">
        <jointName>front_left_wheel_joint</jointName>
        <useForce>1</useForce>
        <multiplier>12.5</multiplier>
        <offset>-0.5</offset>
        <type>VELOCITY</type>
        <p_gain>0.2</p_gain>
        <i_gain>0</i_gain>
        <d_gain>0</d_gain>
        <i_max>-1</i_max>
        <i_min>0</i_min>
        <cmd_max>5</cmd_max>
        <cmd_min>-5</cmd_min>
      </control>

      <!--
        SERVO2_FUNCTION 95 (Script 2)
        SERVO2_MIN 1000
        SERVO2_MAX 2000
      -->
      <control channel="1">
        <jointName>front_right_wheel_joint</jointName>
        <useForce>1</useForce>
        <multiplier>12.5</multiplier>
        <offset>-0.5</offset>
        <type>VELOCITY</type>
        <p_gain>0.2</p_gain>
        <i_gain>0</i_gain>
        <d_gain>0</d_gain>
        <i_max>-1</i_max>
        <i_min>0</i_min>
        <cmd_max>5</cmd_max>
        <cmd_min>-5</cmd_min>
      </control>

      <!--
        SERVO3_FUNCTION 96 (Script 3)
        SERVO3_MIN 1000
        SERVO3_MAX 2000
      -->
      <control channel="2">
        <jointName>mid_left_wheel_joint</jointName>
        <useForce>1</useForce>
        <multiplier>12.5</multiplier>
        <offset>-0.5</offset>
        <type>VELOCITY</type>
        <p_gain>0.2</p_gain>
        <i_gain>0</i_gain>
        <d_gain>0</d_gain>
        <i_max>-1</i_max>
        <i_min>0</i_min>
        <cmd_max>5</cmd_max>
        <cmd_min>-5</cmd_min>
      </control>

      <!--
        SERVO4_FUNCTION 97 (Script 4)
        SERVO4_MIN 1000
        SERVO4_MAX 2000
      -->
      <control channel="3">
        <jointName>mid_right_wheel_joint</jointName>
        <useForce>1</useForce>
        <multiplier>12.5</multiplier>
        <offset>-0.5</offset>
        <type>VELOCITY</type>
        <p_gain>0.2</p_gain>
        <i_gain>0</i_gain>
        <d_gain>0</d_gain>
        <i_max>-1</i_max>
        <i_min>0</i_min>
        <cmd_max>5</cmd_max>
        <cmd_min>-5</cmd_min>
      </control>

      <!--
        SERVO5_FUNCTION 98 (Script 5)
        SERVO5_MIN 1000
        SERVO5_MAX 2000
      -->
      <control channel="4">
        <jointName>back_left_wheel_joint</jointName>
        <useForce>1</useForce>
        <multiplier>12.5</multiplier>
        <offset>-0.5</offset>
        <type>VELOCITY</type>
        <p_gain>0.2</p_gain>
        <i_gain>0</i_gain>
        <d_gain>0</d_gain>
        <i_max>-1</i_max>
        <i_min>0</i_min>
        <cmd_max>5</cmd_max>
        <cmd_min>-5</cmd_min>
      </control>

      <!--
        SERVO6_FUNCTION 99 (Script 6)
        SERVO6_MIN 1000
        SERVO6_MAX 2000
      -->
      <control channel="5">
        <jointName>back_right_wheel_joint</jointName>
        <useForce>1</useForce>
        <multiplier>12.5</multiplier>
        <offset>-0.5</offset>
        <type>VELOCITY</type>
        <p_gain>0.2</p_gain>
        <i_gain>0</i_gain>
        <d_gain>0</d_gain>
        <i_max>-1</i_max>
        <i_min>0</i_min>
        <cmd_max>5</cmd_max>
        <cmd_min>-5</cmd_min>
      </control>

      <!-- Steer servos -->

      <!--
        SERVO7_FUNCTION 100 (Script 7)
        SERVO7_MIN 1000
        SERVO7_MAX 2000
      -->
      <control channel="6">
        <jointName>front_left_steer_joint</jointName>
        <useForce>1</useForce>
        <multiplier>6.283185</multiplier>
        <offset>-0.5</offset>
        <type>POSITION</type>
        <p_gain>5</p_gain>
        <i_gain>0</i_gain>
        <d_gain>0</d_gain>
        <i_max>-1</i_max>
        <i_min>0</i_min>
        <cmd_max>10</cmd_max>
        <cmd_min>-10</cmd_min>
      </control>

      <!--
        SERVO8_FUNCTION 101 (Script 8)
        SERVO8_MIN 1000
        SERVO8_MAX 2000
      -->
      <control channel="7">
        <jointName>front_right_steer_joint</jointName>
        <useForce>1</useForce>
        <multiplier>6.283185</multiplier>
        <offset>-0.5</offset>
        <type>POSITION</type>
        <p_gain>5</p_gain>
        <i_gain>0</i_gain>
        <d_gain>0</d_gain>
        <i_max>-1</i_max>
        <i_min>0</i_min>
        <cmd_max>10</cmd_max>
        <cmd_min>-10</cmd_min>
      </control>

      <!--
        SERVO9_FUNCTION 102 (Script 9)
        SERVO9_MIN 1000
        SERVO9_MAX 2000
      -->
      <control channel="8">
        <jointName>back_left_steer_joint</jointName>
        <useForce>1</useForce>
        <multiplier>6.283185</multiplier>
        <offset>-0.5</offset>
        <type>POSITION</type>
        <p_gain>5</p_gain>
        <i_gain>0</i_gain>
        <d_gain>0</d_gain>
        <i_max>-1</i_max>
        <i_min>0</i_min>
        <cmd_max>10</cmd_max>
        <cmd_min>-10</cmd_min>
      </control>

      <!--
        SERVO10_FUNCTION 103 (Script 10)
        SERVO10_MIN 1000
        SERVO10_MAX 2000
      -->
      <control channel="9">
        <jointName>back_right_steer_joint</jointName>
        <useForce>1</useForce>
        <multiplier>6.283185</multiplier>
        <offset>-0.5</offset>
        <type>POSITION</type>
        <p_gain>5</p_gain>
        <i_gain>0</i_gain>
        <d_gain>0</d_gain>
        <i_max>-1</i_max>
        <i_min>0</i_min>
        <cmd_max>10</cmd_max>
        <cmd_min>-10</cmd_min>
      </control>
    </plugin>

  </model>
</sdf>
