<sdf version='1.7'>
  <model name='skycat_tvbs'>
    <static>0</static>
    <self_collide>0</self_collide>

    <link name='base_link'>
      <inertial>
        <pose>0 0 0 0 0 0</pose>
        <mass>2.6</mass>
        <inertia>
          <ixx>0.010833333</ixx>
          <ixy>0</ixy>
          <ixz>0</ixz>
          <iyy>0.114833333</iyy>
          <iyz>0</iyz>
          <izz>0.108333333</izz>
        </inertia>
      </inertial>
      <collision name='fuselage_collision'>
        <pose>0 0 0 0 0 0</pose>
        <geometry>
          <box>
            <size>0.7 0.1 0.2</size>
          </box>
        </geometry>
      </collision>
      <collision name='wing_collision'>
        <pose>-0.20 0 0.05 0 0 0</pose>
        <geometry>
          <box>
            <size>0.4 1.40 0.04</size>
          </box>
        </geometry>
      </collision>
      <visual name='skycat_base'>
        <geometry>
          <mesh>
            <scale>1 1 1</scale>
            <uri>model://skycat_tvbs/meshes/skycat_base.dae</uri>
          </mesh>
        </geometry>
        <material>
          <ambient>1 1 1</ambient>
          <diffuse>1 1 1</diffuse>
          <specular>0.5 0.5 0.5</specular>
          <pbr>
            <metal>
              <albedo_map>model://skycat_tvbs/materials/textures/skycat.png</albedo_map>
              <roughness>0.5</roughness>
              <metalness>0.5</metalness> 
            </metal>
          </pbr>
        </material>
      </visual>
      <!-- <visual name='skycat_elevon_left'>
        <geometry>
          <mesh>
            <scale>1 1 1</scale>
            <uri>model://skycat_tvbs/meshes/skycat_elevon_left.dae</uri>
          </mesh>
        </geometry>
      </visual>
      <visual name='skycat_elevon_right'>
        <geometry>
          <mesh>
            <scale>1 1 1</scale>
            <uri>model://skycat_tvbs/meshes/skycat_elevon_right.dae</uri>
          </mesh>
        </geometry>
      </visual>
      <visual name='skycat_tilt_left'>
        <geometry>
          <mesh>
            <scale>1 1 1</scale>
            <uri>model://skycat_tvbs/meshes/skycat_tilt_left.dae</uri>
          </mesh>
        </geometry>
      </visual>
      <visual name='skycat_tilt_right'>
        <geometry>
          <mesh>
            <scale>1 1 1</scale>
            <uri>model://skycat_tvbs/meshes/skycat_tilt_right.dae</uri>
          </mesh>
        </geometry>
      </visual> -->

      <!-- save for debugging use -->
      <!-- <visual name="cp_wing">
        <pose>0.01 0 0.042 0 0 0</pose>
        <geometry>
          <sphere>
            <radius>0.03</radius>
          </sphere>
        </geometry>
        <material>
          <ambient>0 0 1</ambient>
          <diffuse>0 0 1</diffuse>
          <specular>0.1 0.1 0.1 1</specular>
        </material>
      </visual>
      <visual name="cp_left_elevon">
        <pose>-0.27 0.322 0.042 0 0 0</pose>
        <geometry>
          <sphere>
            <radius>0.03</radius>
          </sphere>
        </geometry>
        <material>
          <ambient>1 0 0</ambient>
          <diffuse>1 0 0</diffuse>
          <specular>0.1 0.1 0.1 1</specular>
        </material>
      </visual>
      <visual name="cp_right_elevon">
        <pose>-0.27 -0.322 0.042 0 0 0</pose>
        <geometry>
          <sphere>
            <radius>0.03</radius>
          </sphere>
        </geometry>
        <material>
          <ambient>0 1 0</ambient>
          <diffuse>0 1 0</diffuse>
          <specular>0.1 0.1 0.1 1</specular>
        </material>
      </visual>
      <visual name="cp_left_winglet">
        <pose>-0.4 0.735 0.08 0 0 0</pose>
        <geometry>
          <sphere>
            <radius>0.03</radius>
          </sphere>
        </geometry>
        <material>
          <ambient>1 0 0</ambient>
          <diffuse>1 0 0</diffuse>
          <specular>0.1 0.1 0.1 1</specular>
        </material>
      </visual>
      <visual name="cp_right_winglet">
        <pose>-0.4 -0.735 0.08 0 0 0</pose>
        <geometry>
          <sphere>
            <radius>0.03</radius>
          </sphere>
        </geometry>
        <material>
          <ambient>0 1 0</ambient>
          <diffuse>0 1 0</diffuse>
          <specular>0.1 0.1 0.1 1</specular>
        </material>
      </visual> -->

    </link>

    <link name="elevon_left_link">
      <inertial>
        <pose>-0.30 0.37 0.037 0 0 0.366519</pose>
        <mass>0.1</mass>
        <inertia>
          <ixx>0.003713333</ixx>
          <ixy>0</ixy>
          <iyy>0.000104167</iyy>
          <ixz>0</ixz>
          <iyz>0</iyz>
          <izz>0.003650833</izz>
        </inertia>
      </inertial>
      <collision name="collision">
        <pose>-0.30 0.37 0.037 0 0 0.366519</pose>
        <geometry>
          <box>
            <size>0.05 0.66 0.01</size>
          </box>
        </geometry>
      </collision>
      <visual name='visual'>
        <geometry>
          <mesh>
            <scale>1 1 1</scale>
            <uri>model://skycat_tvbs/meshes/skycat_elevon_left.dae</uri>
          </mesh>
        </geometry>
        <material>
          <ambient>1 1 1</ambient>
          <diffuse>1 1 1</diffuse>
          <specular>0.5 0.5 0.5</specular>
          <pbr>
            <metal>
              <albedo_map>model://skycat_tvbs/materials/textures/skycat.png</albedo_map>
              <roughness>0.5</roughness>
              <metalness>0.5</metalness> 
            </metal>
          </pbr>
        </material>
      </visual>
    </link>
    <joint name="elevon_left_joint" type="revolute">
      <pose relative_to='base_link'>-0.263 0.327 0.037 0 0 0.366519</pose>
      <parent>base_link</parent>
      <child>elevon_left_link</child>
      <axis>
        <xyz>0 1 0</xyz>
        <limit>
          <lower>-0.523599</lower>
          <upper>0.523599</upper>
        </limit>
        <dynamics>
          <damping>0.02</damping>
        </dynamics>
      </axis>
    </joint>

    <link name="elevon_right_link">
      <inertial>
        <pose>-0.30 -0.37 0.037 0 0 -0.366519</pose>
        <mass>0.1</mass>
        <inertia>
          <ixx>0.003713333</ixx>
          <ixy>0</ixy>
          <iyy>0.000104167</iyy>
          <ixz>0</ixz>
          <iyz>0</iyz>
          <izz>0.003650833</izz>
        </inertia>
      </inertial>
      <collision name="collision">
        <pose>-0.30 -0.37 0.037 0 0 -0.366519</pose>
        <geometry>
          <box>
            <size>0.05 0.66 0.01</size>
          </box>
        </geometry>
      </collision>
      <visual name='visual'>
        <geometry>
          <mesh>
            <scale>1 1 1</scale>
            <uri>model://skycat_tvbs/meshes/skycat_elevon_right.dae</uri>
          </mesh>
        </geometry>
        <material>
          <ambient>1 1 1</ambient>
          <diffuse>1 1 1</diffuse>
          <specular>0.5 0.5 0.5</specular>
          <pbr>
            <metal>
              <albedo_map>model://skycat_tvbs/materials/textures/skycat.png</albedo_map>
              <roughness>0.5</roughness>
              <metalness>0.5</metalness> 
            </metal>
          </pbr>
        </material>
      </visual>
    </link>
    <joint name="elevon_right_joint" type="revolute">
      <pose relative_to='base_link'>-0.263 -0.327 0.037 0 0 -0.366519</pose>
      <parent>base_link</parent>
      <child>elevon_right_link</child>
      <axis>
        <xyz>0 1 0</xyz>
        <limit>
          <lower>-0.523599</lower>
          <upper>0.523599</upper>
        </limit>
        <dynamics>
          <damping>0.02</damping>
        </dynamics>
      </axis>
    </joint>

    <link name="tilt_left_link">
      <inertial>
        <pose>0.091 0.327 0.042 0 1.570796 0</pose>
        <mass>0.06</mass>
        <inertia>
          <ixx>0.0000125</ixx>
          <ixy>0</ixy>
          <ixz>0</ixz>
          <iyy>0.0000125</iyy>
          <iyz>0</iyz>
          <izz>0.00001875</izz>
        </inertia>
      </inertial>
      <collision name='collision'>
        <pose>0.091 0.327 0.042 0 1.570796 0</pose>
        <geometry>
          <cylinder>
            <radius>0.025</radius>
            <length>0.025</length>
          </cylinder>
        </geometry>
      </collision>
      <visual name='visual'>
        <geometry>
          <mesh>
            <scale>1 1 1</scale>
            <uri>model://skycat_tvbs/meshes/skycat_tilt_left.dae</uri>
          </mesh>
        </geometry>
        <material>
          <ambient>1 1 1</ambient>
          <diffuse>1 1 1</diffuse>
          <specular>0.3 0.3 0.3</specular>
          <pbr>
            <metal>
              <albedo_map>model://skycat_tvbs/materials/textures/skycat.png</albedo_map>
              <roughness>0.5</roughness>
              <metalness>0.9</metalness> 
            </metal>
          </pbr>
        </material>
      </visual>
    </link>
    <joint name="tilt_left_joint" type="revolute">
      <pose relative_to='base_link'>0.091 0.327 0.042 0 0 0</pose>
      <parent>base_link</parent>
      <child>tilt_left_link</child>
      <axis>
        <xyz>0 1 0</xyz>
        <limit>
          <lower>-1.047198</lower>
          <upper>1.047198</upper>
        </limit>
        <dynamics>
          <damping>0.02</damping>
        </dynamics>
      </axis>
    </joint>

    <link name="tilt_right_link">
      <inertial>
        <pose>0.091 -0.327 0.042 0 1.570796 0</pose>
        <mass>0.06</mass>
        <inertia>
          <ixx>0.0000125</ixx>
          <ixy>0</ixy>
          <ixz>0</ixz>
          <iyy>0.0000125</iyy>
          <iyz>0</iyz>
          <izz>0.00001875</izz>
        </inertia>
      </inertial>
      <collision name='collision'>
        <pose>0.091 -0.327 0.042 0 1.570796 0</pose>
        <geometry>
          <cylinder>
            <radius>0.025</radius>
            <length>0.025</length>
          </cylinder>
        </geometry>
      </collision>
      <visual name='visual'>
        <geometry>
          <mesh>
            <scale>1 1 1</scale>
            <uri>model://skycat_tvbs/meshes/skycat_tilt_right.dae</uri>
          </mesh>
        </geometry>
        <material>
          <ambient>1 1 1</ambient>
          <diffuse>1 1 1</diffuse>
          <specular>0.3 0.3 0.3</specular>
          <pbr>
            <metal>
              <albedo_map>model://skycat_tvbs/materials/textures/skycat.png</albedo_map>
              <roughness>0.5</roughness>
              <metalness>0.9</metalness> 
            </metal>
          </pbr>
        </material>
      </visual>
    </link>
    <joint name="tilt_right_joint" type="revolute">
      <pose relative_to='base_link'>0.091 -0.327 0.042 0 0 0</pose>
      <parent>base_link</parent>
      <child>tilt_right_link</child>
      <axis>
        <xyz>0 1 0</xyz>
        <limit>
          <lower>-1.047198</lower>
          <upper>1.047198</upper>
        </limit>
        <dynamics>
          <damping>0.02</damping>
        </dynamics>
      </axis>
    </joint>

    <link name="motor_left_link">
      <pose relative_to='motor_left_joint'>0 0 0.03 0 0 0</pose>
      <inertial>
        <pose>0 0 0 0 0 0</pose>
        <mass>0.025</mass>
        <inertia>
          <ixx>9.75e-06</ixx>
          <ixy>0</ixy>
          <ixz>0</ixz>
          <iyy>0.000166704</iyy>
          <iyz>0</iyz>
          <izz>0.000167604</izz>
        </inertia>
      </inertial>
      <collision name='collision'>
        <pose>0 0 0.025 0 0 0</pose>
        <geometry>
          <cylinder>
            <length>0.005</length>
            <radius>0.13</radius>
          </cylinder>
        </geometry>
      </collision>
      <!-- <visual name='motor_visual'>
        <geometry>
          <cylinder>
            <radius>0.025</radius>
            <length>0.025</length>
          </cylinder>
        </geometry>
      </visual> -->
      <visual name='prop_visual'>
        <pose>0 0 0.025 0 0 0</pose>
        <geometry>
          <mesh>
            <scale>1 1 1</scale>
            <uri>model://skycat_tvbs/meshes/iris_prop_cw.dae</uri>
          </mesh>
        </geometry>
        <material>
          <diffuse>1.0 1.0 1.0</diffuse>
          <specular>1.0 1.0 1.0</specular>
          <pbr>
            <metal>
              <albedo_map>model://skycat_tvbs/materials/textures/metal_graphite/metal_graphite_basecolor.jpg</albedo_map>
              <metalness_map>model://skycat_tvbs/materials/textures/metal_graphite/metal_graphite_metallic.jpg</metalness_map>
              <normal_map>model://skycat_tvbs/materials/textures/metal_graphite/metal_graphite_normal.jpg</normal_map>
              <roughness_map>model://skycat_tvbs/materials/textures/metal_graphite/metal_graphite_roughness.jpg</roughness_map>
              <roughness>1.0</roughness>
              <metalness>1.0</metalness> 
            </metal>
          </pbr>
        </material>
      </visual>
    </link>
    <joint name="motor_left_joint" type="revolute">
      <pose relative_to='tilt_left_joint'>0 0 0 0 1.570796 0</pose>
      <parent>tilt_left_link</parent>
      <child>motor_left_link</child>
      <axis>
        <xyz>0 0 1</xyz>
        <limit>
          <lower>-1e16</lower>
          <upper>1e16</upper>
        </limit>
        <dynamics>
          <damping>0.002</damping>
        </dynamics>
        <use_parent_model_frame>1</use_parent_model_frame>
      </axis>
    </joint>

    <link name="motor_right_link">
      <pose relative_to='motor_right_joint'>0 0 0.03 0 0 0</pose>
      <inertial>
        <pose>0 0 0 0 0 0</pose>
        <mass>0.025</mass>
        <inertia>
          <ixx>9.75e-06</ixx>
          <ixy>0</ixy>
          <ixz>0</ixz>
          <iyy>0.000166704</iyy>
          <iyz>0</iyz>
          <izz>0.000167604</izz>
        </inertia>
      </inertial>
      <collision name='collision'>
        <pose>0 0 0.025 0 0 0</pose>
        <geometry>
          <cylinder>
            <length>0.005</length>
            <radius>0.13</radius>
          </cylinder>
        </geometry>
      </collision>
      <!-- <visual name='motor_visual'>
        <geometry>
          <cylinder>
            <radius>0.025</radius>
            <length>0.025</length>
          </cylinder>
        </geometry>
      </visual> -->
      <visual name='prop_visual'>
        <pose>0 0 0.025 0 0 0</pose>
        <geometry>
          <mesh>
            <scale>1 1 1</scale>
            <uri>model://skycat_tvbs/meshes/iris_prop_ccw.dae</uri>
          </mesh>
        </geometry>
        <material>
          <diffuse>1.0 1.0 1.0</diffuse>
          <specular>1.0 1.0 1.0</specular>
          <pbr>
            <metal>
              <albedo_map>model://skycat_tvbs/materials/textures/metal_graphite/metal_graphite_basecolor.jpg</albedo_map>
              <metalness_map>model://skycat_tvbs/materials/textures/metal_graphite/metal_graphite_metallic.jpg</metalness_map>
              <normal_map>model://skycat_tvbs/materials/textures/metal_graphite/metal_graphite_normal.jpg</normal_map>
              <roughness_map>model://skycat_tvbs/materials/textures/metal_graphite/metal_graphite_roughness.jpg</roughness_map>
              <roughness>1.0</roughness>
              <metalness>1.0</metalness> 
            </metal>
          </pbr>
        </material>
      </visual>
    </link>
    <joint name="motor_right_joint" type="revolute">
      <pose relative_to='tilt_right_joint'>0 0 0 0 1.570796 0</pose>
      <parent>tilt_right_link</parent>
      <child>motor_right_link</child>
      <axis>
        <xyz>0 0 1</xyz>
        <limit>
          <lower>-1e16</lower>
          <upper>1e16</upper>
        </limit>
        <dynamics>
          <damping>0.002</damping>
        </dynamics>
      </axis>
    </joint>

    <!-- sensors -->
    <link name='imu_link'>
      <inertial>
        <pose>0 0 0 0 0 0</pose>
        <mass>0.15</mass>
        <inertia>
          <ixx>0.00002</ixx>
          <ixy>0</ixy>
          <ixz>0</ixz>
          <iyy>0.00002</iyy>
          <iyz>0</iyz>
          <izz>0.00002</izz>
        </inertia>
      </inertial>
      <sensor name="imu_sensor" type="imu">
        <pose degrees="true">0 0 0 180 0 0</pose>
        <always_on>1</always_on>
        <update_rate>1000.0</update_rate>
      </sensor>
    </link>
    <joint name='imu_joint' type='revolute'>
      <child>imu_link</child>
      <parent>base_link</parent>
      <axis>
        <xyz>0 0 1</xyz>
        <limit>
          <lower>0</lower>
          <upper>0</upper>
          <effort>0</effort>
          <velocity>0</velocity>
        </limit>
        <dynamics>
          <damping>1.0</damping>
        </dynamics>
        <use_parent_model_frame>1</use_parent_model_frame>
      </axis>
    </joint>

    <!-- plugins -->
    <plugin filename="gz-sim-joint-state-publisher-system"
      name="gz::sim::systems::JointStatePublisher">
    </plugin>

    <!-- prop_left (cc) lift-drag -->
    <plugin filename="gz-sim-lift-drag-system"
        name="gz::sim::systems::LiftDrag">
      <a0>0.3</a0>
      <alpha_stall>1.4</alpha_stall>
      <cla>4.2500</cla>
      <cda>0.10</cda>
      <cma>0.0</cma>
      <cla_stall>-0.025</cla_stall>
      <cda_stall>0.0</cda_stall>
      <cma_stall>0.0</cma_stall>
      <area>0.002</area>
      <air_density>1.2041</air_density>
      <cp>0.084 0 0</cp>
      <forward>0 -1 0</forward>
      <upward>0 0 1</upward>
      <link_name>motor_left_link</link_name>
    </plugin>
    <plugin filename="gz-sim-lift-drag-system"
        name="gz::sim::systems::LiftDrag">
      <a0>0.3</a0>
      <alpha_stall>1.4</alpha_stall>
      <cla>4.2500</cla>
      <cda>0.10</cda>
      <cma>0.0</cma>
      <cla_stall>-0.025</cla_stall>
      <cda_stall>0.0</cda_stall>
      <cma_stall>0.0</cma_stall>
      <area>0.002</area>
      <air_density>1.2041</air_density>
      <cp>-0.084 0 0</cp>
      <forward>0 1 0</forward>
      <upward>0 0 1</upward>
      <link_name>motor_left_link</link_name>
    </plugin>

    <!-- prop_right (ccw) lift-drag -->
    <plugin filename="gz-sim-lift-drag-system"
        name="gz::sim::systems::LiftDrag">
      <a0>0.3</a0>
      <alpha_stall>1.4</alpha_stall>
      <cla>4.2500</cla>
      <cda>0.10</cda>
      <cma>0.0</cma>
      <cla_stall>-0.025</cla_stall>
      <cda_stall>0.0</cda_stall>
      <cma_stall>0.0</cma_stall>
      <area>0.002</area>
      <air_density>1.2041</air_density>
      <cp>0.084 0 0</cp>
      <forward>0 1 0</forward>
      <upward>0 0 1</upward>
      <link_name>motor_right_link</link_name>
    </plugin>
    <plugin filename="gz-sim-lift-drag-system"
        name="gz::sim::systems::LiftDrag">
      <a0>0.3</a0>
      <alpha_stall>1.4</alpha_stall>
      <cla>4.2500</cla>
      <cda>0.10</cda>
      <cma>0.0</cma>
      <cla_stall>-0.025</cla_stall>
      <cda_stall>0.0</cda_stall>
      <cma_stall>0.0</cma_stall>
      <area>0.002</area>
      <air_density>1.2041</air_density>
      <cp>-0.084 0 0</cp>
      <forward>0 -1 0</forward>
      <upward>0 0 1</upward>
      <link_name>motor_right_link</link_name>
    </plugin>

    <!-- wing lift-drag -->
    <plugin filename="gz-sim-lift-drag-system"
        name="gz::sim::systems::LiftDrag">
      <a0>0.13</a0>
      <cla>3.7</cla>
      <cda>0.06417112299</cda>
      <cma>0.0</cma>
      <alpha_stall>0.3391428111</alpha_stall>
      <cla_stall>-3.85</cla_stall>
      <cda_stall>-0.9233984055</cda_stall>
      <cma_stall>0.0</cma_stall>
      <cp>0.01 0 0.042</cp>
      <area>0.60</area>
      <air_density>1.2041</air_density>
      <forward>1 0 0</forward>
      <upward>0 0 1</upward>
      <link_name>base_link</link_name>
    </plugin>
    <!-- left_elevon lift-drag -->
    <plugin filename="gz-sim-lift-drag-system"
        name="gz::sim::systems::LiftDrag">
      <a0>0.15</a0>
      <cla>6.8</cla>
      <cda>0.06417112299</cda>
      <cma>0.0</cma>
      <alpha_stall>0.6391428111</alpha_stall>
      <cla_stall>-3.85</cla_stall>
      <cda_stall>-0.9233984055</cda_stall>
      <cma_stall>0.0</cma_stall>
      <cp>-0.27 0.322 -0.042</cp>
      <area>0.033</area>
      <air_density>1.2041</air_density>
      <forward>1 0 0</forward>
      <upward>0 0 1</upward>
      <link_name>base_link</link_name>
      <control_joint_name>elevon_left_joint</control_joint_name>
      <control_joint_rad_to_cl>-5.0</control_joint_rad_to_cl>
    </plugin>
    <!-- right_elevon lift-drag -->
    <plugin filename="gz-sim-lift-drag-system"
        name="gz::sim::systems::LiftDrag">
      <a0>0.15</a0>
      <cla>6.8</cla>
      <cda>0.06417112299</cda>
      <cma>0.0</cma>
      <alpha_stall>0.6391428111</alpha_stall>
      <cla_stall>-3.85</cla_stall>
      <cda_stall>-0.9233984055</cda_stall>
      <cma_stall>0.0</cma_stall>
      <cp>-0.27 -0.322 -0.042</cp>
      <area>0.033</area>
      <air_density>1.2041</air_density>
      <forward>1 0 0</forward>
      <upward>0 0 1</upward>
      <link_name>base_link</link_name>
      <control_joint_name>elevon_right_joint</control_joint_name>
      <control_joint_rad_to_cl>-5.0</control_joint_rad_to_cl>
    </plugin>
    <!-- left_winglet lift-drag -->
    <plugin filename="gz-sim-lift-drag-system"
        name="gz::sim::systems::LiftDrag">
      <a0>0.0</a0>
      <cla>4.752798721</cla>
      <cda>0.6417112299</cda>
      <cma>0.0</cma>
      <alpha_stall>0.3391428111</alpha_stall>
      <cla_stall>-3.85</cla_stall>
      <cda_stall>-0.9233984055</cda_stall>
      <cma_stall>0.0</cma_stall>
      <cp>-0.4 0.735 0.08</cp>
      <area>0.12</area>
      <air_density>1.2041</air_density>
      <forward>1 0 0</forward>
      <upward>0 1 0</upward>
      <link_name>base_link</link_name>
    </plugin>
    <!-- right_winglet lift-drag -->
    <plugin filename="gz-sim-lift-drag-system"
        name="gz::sim::systems::LiftDrag">
      <a0>0.0</a0>
      <cla>4.752798721</cla>
      <cda>0.6417112299</cda>
      <cma>0.0</cma>
      <alpha_stall>0.3391428111</alpha_stall>
      <cla_stall>-3.85</cla_stall>
      <cda_stall>-0.9233984055</cda_stall>
      <cma_stall>0.0</cma_stall>
      <cp>-0.4 -0.735 0.08</cp>
      <area>0.12</area>
      <air_density>1.2041</air_density>
      <forward>1 0 0</forward>
      <upward>0 -1 0</upward>
      <link_name>base_link</link_name>
    </plugin>

    <plugin filename="gz-sim-apply-joint-force-system"
      name="gz::sim::systems::ApplyJointForce">
      <joint_name>elevon_left_joint</joint_name>
    </plugin>
    <plugin filename="gz-sim-apply-joint-force-system"
      name="gz::sim::systems::ApplyJointForce">
      <joint_name>elevon_right_joint</joint_name>
    </plugin>
    <plugin filename="gz-sim-apply-joint-force-system"
      name="gz::sim::systems::ApplyJointForce">
      <joint_name>tilt_left_joint</joint_name>
    </plugin>
    <plugin filename="gz-sim-apply-joint-force-system"
      name="gz::sim::systems::ApplyJointForce">
      <joint_name>tilt_right_joint</joint_name>
    </plugin>
    <plugin filename="gz-sim-apply-joint-force-system"
      name="gz::sim::systems::ApplyJointForce">
      <joint_name>motor_left_joint</joint_name>
    </plugin>
    <plugin filename="gz-sim-apply-joint-force-system"
      name="gz::sim::systems::ApplyJointForce">
      <joint_name>motor_right_joint</joint_name>
    </plugin>

    <plugin name="ArduPilotPlugin" filename="ArduPilotPlugin">
      <!-- Port settings -->
      <fdm_addr>127.0.0.1</fdm_addr>
      <fdm_port_in>9002</fdm_port_in>
      <connectionTimeoutMaxCount>5</connectionTimeoutMaxCount>
      <lock_step>1</lock_step>

      <!-- Frame conventions
        modelXYZToAirplaneXForwardZDown:
          - transforms body frame from orientation in Gazebo to NED

        gazeboXYZToNED
          - transforms world from Gazebo convention xyz = N -E -D
            to ArduPilot convention xyz = NED

        Vehicle is oriented x-forward, y-left, z-up
      -->
      <modelXYZToAirplaneXForwardZDown degrees="true">0 0 0 180 0 0</modelXYZToAirplaneXForwardZDown>
      <gazeboXYZToNED degrees="true">0 0 0 180 0 90</gazeboXYZToNED>

      <!-- Sensors -->
      <imuName>imu_sensor</imuName>

      <!-- 
          SERVO1_FUNCTION   77 (Elevon Left)
          SERVO1_MAX        2000
          SERVO1_MIN        1000
          SERVO1_REVERSED   0
          SERVO1_TRIM       1500

          pwm:          =>  [1000, 2000] 
          input:        =>  [0, 1]
          offset: -0.5  =>  [-0.5, 0.5]
          scale:   2.0  =>  [-1.0, 1.0]
          scale: 0.524  =>  [-0.524, 0.524]
       -->
      <control channel="0">
        <jointName>elevon_left_joint</jointName>
        <useForce>1</useForce>
        <multiplier>1.047</multiplier>
        <offset>-0.5</offset>
        <servo_min>1000</servo_min>
        <servo_max>2000</servo_max>
        <type>POSITION</type>
        <p_gain>5.0</p_gain>
        <i_gain>0</i_gain>
        <d_gain>0</d_gain>
        <i_max>-1</i_max>
        <i_min>0</i_min>
        <cmd_max>2.5</cmd_max>
        <cmd_min>-2.5</cmd_min>
      </control>

      <!-- 
          SERVO2_FUNCTION   78 (Elevon Right)
          SERVO2_MAX        2000
          SERVO2_MIN        1000
          SERVO2_REVERSED   0
          SERVO2_TRIM       1500
       -->
      <control channel="1">
        <jointName>elevon_right_joint</jointName>
        <useForce>1</useForce>
        <multiplier>1.047</multiplier>
        <offset>-0.5</offset>
        <servo_min>1000</servo_min>
        <servo_max>2000</servo_max>
        <type>POSITION</type>
        <p_gain>5.0</p_gain>
        <i_gain>0</i_gain>
        <d_gain>0</d_gain>
        <i_max>-1</i_max>
        <i_min>0</i_min>
        <cmd_max>2.5</cmd_max>
        <cmd_min>-2.5</cmd_min>
      </control>

      <!-- 
          SERVO3_FUNCTION   75 (Left Motor Tilt)
          SERVO3_MAX        2000
          SERVO3_MIN        1000
          SERVO3_REVERSED   0
          SERVO3_TRIM       1500

          Tilt is +/- 60 deg (1.04719755 rad)
       -->
      <control channel="2">
        <jointName>tilt_left_joint</jointName>
        <useForce>1</useForce>
        <multiplier>2.094395</multiplier>
        <offset>-0.5</offset>
        <servo_min>2000</servo_min>
        <servo_max>1000</servo_max>
        <type>POSITION</type>
        <p_gain>10.0</p_gain>
        <i_gain>0</i_gain>
        <d_gain>0</d_gain>
        <i_max>-1</i_max>
        <i_min>0</i_min>
        <cmd_max>2.5</cmd_max>
        <cmd_min>-2.5</cmd_min>
      </control>

      <!-- 
          SERVO4_FUNCTION   76 (Right Motor Tilt)
          SERVO4_MAX        2000
          SERVO4_MIN        1000
          SERVO4_REVERSED   0
          SERVO4_TRIM       1500

          Tilt is +/- 60 deg (1.04719755 rad)
       -->
      <control channel="3">
        <jointName>tilt_right_joint</jointName>
        <useForce>1</useForce>
        <multiplier>-2.094395</multiplier>
        <offset>-0.5</offset>
        <servo_min>1000</servo_min>
        <servo_max>2000</servo_max>
        <type>POSITION</type>
        <p_gain>10.0</p_gain>
        <i_gain>0</i_gain>
        <d_gain>0</d_gain>
        <i_max>-1</i_max>
        <i_min>0</i_min>
        <cmd_max>2.5</cmd_max>
        <cmd_min>-2.5</cmd_min>
      </control>

      <!-- 
          SERVO5_FUNCTION   73 (Left Motor CW)
          SERVO5_MAX        2000
          SERVO5_MIN        1000
          SERVO5_REVERSED   0
          SERVO5_TRIM       1000
       -->
      <control channel="4">
        <jointName>motor_left_joint</jointName>
        <useForce>1</useForce>
        <multiplier>-1500</multiplier>
        <offset>0</offset>
        <servo_min>1000</servo_min>
        <servo_max>2000</servo_max>
        <type>VELOCITY</type>
        <p_gain>0.20</p_gain>
        <i_gain>0</i_gain>
        <d_gain>0</d_gain>
        <i_max>-1</i_max>
        <i_min>0</i_min>
        <cmd_max>2.5</cmd_max>
        <cmd_min>-2.5</cmd_min>
      </control>

      <!-- 
          SERVO6_FUNCTION   74 (Right Motor CCW)
          SERVO6_MAX        2000
          SERVO6_MIN        1000
          SERVO6_REVERSED   0
          SERVO6_TRIM       1500
       -->
      <control channel="5">
        <jointName>motor_right_joint</jointName>
        <useForce>1</useForce>
        <multiplier>1500</multiplier>
        <offset>0</offset>
        <servo_min>1000</servo_min>
        <servo_max>2000</servo_max>
        <type>VELOCITY</type>
        <p_gain>0.20</p_gain>
        <i_gain>0</i_gain>
        <d_gain>0</d_gain>
        <i_max>-1</i_max>
        <i_min>0</i_min>
        <cmd_max>2.5</cmd_max>
        <cmd_min>-2.5</cmd_min>
      </control>

    </plugin>

  </model>
</sdf>
